Workbook

Sheet extrato-literarius
A1: Tipo | B1: Número | D1: Documento | E1: Descrição | F1: Valor | G1: Origem | H1: Plano de Contas | I1: Centro Resultados | J1: Conta contábil
A2: D | B2: 20545 | C2: 46024 | D2: 20545 | E2: CONTABIL RIBEIRO | F2: -6505 | G2: BAIXA | H2: Contabilidade | I2: Administrativo | J2: =VLOOKUP(H2,Planilha1!B:C,2,0) -> 214
A3: D | B3: 20581 | C3: 46024 | D3: 20581 | E3: Porto Saúde S.A | F3: -1710.17 | G3: BAIXA | H3: Assistencia Medica | I3: Administrativo | J3: =VLOOKUP(H3,Planilha1!B:C,2,0) -> 200
A4: D | B4: 23083 | C4: 46024 | D4: 23083 | E4: FLEXPACK INDUSTRIA E COMERCIO DE EMBALAGENS LTDA | F4: -3289.16 | G4: BAIXA | H4: Materiais Aplicados Venda Prod | I4: Expedição | J4: =VLOOKUP(H4,Planilha1!B:C,2,0) -> 224
A5: D | B5: 10628 | C5: 46024 | D5: 10628 | E5: EDITORA HAGNOS LTDA | F5: -270.72 | G5: BAIXA | H5: Materiais Para Revenda | I5: CPC Offline | J5: =VLOOKUP(H5,Planilha1!B:C,2,0) -> 80
A6: D | B6: 23161 | C6: 46024 | D6: 23161 | E6: Marcos Roberto Loiola Arrais | F6: -1105 | G6: BAIXA | H6: Despesas Editorial - Edição | I6: Editorial | J6: =VLOOKUP(H6,Planilha1!B:C,2,0) -> 185
A7: D | B7: 23125 | C7: 46024 | D7: 23125 | E7: GUILHERME JUNIOR GUIMARAES | F7: -810 | G7: BAIXA | H7: Despesas Editorial - Revisão de Prova | I7: Editorial | J7: =VLOOKUP(H7,Planilha1!B:C,2,0) -> 752
A8: D | B8: 23154 | C8: 46024 | D8: 23154 | E8: GUILHERME JUNIOR GUIMARAES | F8: -78 | G8: BAIXA | H8: Despesas Editorial - Revisão de Prova | I8: Editorial | J8: =VLOOKUP(H8,Planilha1!B:C,2,0) -> 752
A9: D | B9: 10625 | C9: 46024 | D9: 10625 | E9: VIDA MELHOR EDITORA LTDA | F9: -4796.51 | G9: BAIXA | H9: Materiais Para Revenda | I9: CPC Offline | J9: =VLOOKUP(H9,Planilha1!B:C,2,0) -> 80
A10: C | B10: 1925 | C10: 46024 | D10: 1925 | E10: TED RECEBIDA 4080447700014 | F10: 19598.72 | G10: BANCÁRIO | H10: TRANSFERENCIA ENTRE CONTAS | I10: TRANSFERENCIAS ENTRE CONTAS | J10: =VLOOKUP(H10,Planilha1!B:C,2,0) -> 0
A11: C | B11: 1926 | C11: 46024 | D11: 1926 | E11: PIX RECEBIDO 07290754867 | F11: 160 | G11: BANCÁRIO | H11: VENDA DE LIVROS | I11: Receita de vendas | J11: =VLOOKUP(H11,Planilha1!B:C,2,0) -> 132 a 134
A12: D | B12: 15870 | C12: 46024 | D12: 15870 | E12: Luz Para o Caminho | F12: -725 | G12: BAIXA | H12: Materiais Para Revenda | I12: CPC Offline | J12: =VLOOKUP(H12,Planilha1!B:C,2,0) -> 80
A13: D | B13: 5128 | C13: 46027 | D13: 5128 | E13: EDITORA HAGNOS LTDA | F13: -1586.1 | G13: BAIXA | H13: Materiais Para Revenda | I13: CPC Offline | J13: =VLOOKUP(H13,Planilha1!B:C,2,0) -> 80
... A317: C | B317: 2599 | C317: 46052 | D317: 2599 | E317: RENDIMENTO LIQUIDO DE CONTAMAX | F317: 5.91 | G317: BANCÁRIO | H317: Receitas financeiras | I317: Financeiro | J317: =VLOOKUP(H317,Planilha1!B:C,2,0) -> 135

Sheet Planilha1
A1: Codigo | B1: Descrição | C1: Contas contábeis
A2: 0 | B2: Cod 0561 | Cod 1082 | Cod 1138 | Cod 1170 | Cod 1176 | Cod 1191 | Cod 1196 | Cod 1200 | Cod 1646 | Cod 8301 | C2: 62
A3: 2 | B3: VENDA DE LIVROS | C3: 132 a 134
A4: 3 | B4: AQUISIÇÃO DE LIVROS | C4: 28
A5: 4 | B5: VENDA DE EBOOK | C5: 134
A6: 10 | B6: 13º Salário | C6: 180 a 192
A7: 11 | B7: Despesas Editorial - Capa | C7: 752
A8: 12 | B8: Despesas Editorial - Conferência de Emendas | Despesas Editorial - Revisão de Prova | C8: 752
A9: 13 | B9: Despesas Editorial - Diagramação | C9: 185
A10: 14 | B10: Despesas Editorial - Edição | C10: 185
A11: 15 | B11: Despesas Editorial - Ilustração | C11: 752
A12: 16 | B12: Despesas Editorial - Preparação | C12: 752
A13: 17 | B13: Despesas Editorial - Produção Editorial | C13: 752
A14: 18 | B14: Despesas Editorial - Revisão de Prova | C14: 752
A15: 19 | B15: Despesas Editorial - Tradução | C15: 752
A16: 20 | B16: Materiais Para Revenda | C16: 80
A17: 21 | B17: Producao Material Proprio | C17: 80
A18: 21 | B18: Produção Material Próprio | C18: 80
... A75: 77 | B75: Impostos E Taxas | C75: 225
A76: 78 | B76: Estorno e Reembolso | C76: 231 LANÇAR NA NATUREZA DA DESPESA
A77: 79 | B77: Internet | C77: 233
A78: 80 | B78: Monitoramento Sede | C78: 67
A79: 81 | B79: Royalties | C79: 165
A80: 82 | B80: PIS 8301 | C80: 197
A81: 83 | B81: Terreno e Dependências - Sede | C81: 255
A82: 84 | B82: Sistemas e Softwares -Adm Marketing | C82: 244
A83: 85 | B83: Sistemas e Softwares Comerciais | C83: 710
A84: 86 | B84: Devolução de Venda | C84: 166
A85: 87 | B85: Exames médicos | C85: 193
A86: 88 | B86: Juros pagos/passivos | C86: 251
A87: 89 | B87: Lanches e Refeições Equipe | C87: 215
A88: 90 | B88: Lanches e Refeições Comercial | C88: 212
... A99: 101 | B99: Condomínio | C99: 237
A100: 102 | B100: DESPESAS OPERACIONAIS | C100: 4.3.1
A101: 103 | B101: DESPESAS ADMINISTRATIVAS | C101: 4.3.1.01
A102: 104 | B102: Materiais Impressos | C102: 224
A103: 105 | B103: Cod 0561 | C103: 67
A104: 106 | B104: TRANSFERENCIA ENTRE CONTAS | C104: 0
A105: 107 | B105: Despesas Bancárias | C105: 252
A106: 108 | B106: Rescisões | C106: 188 A 192
...

Sheet extrato-santander
A1: AGENCIA | B1: 0729 | C1: CONTA | D1: 130020815
A2: 02/01/2026 | B2: PIX RECEBIDO 07290754867 | D2: 160 | E2: 413670.59
A3: 02/01/2026 | B3: TED RECEBIDA 40804477000144 | D3: 19598.72 | E3: 413510.59
A4: 02/01/2026 | B4: PIX ENVIADO 53 321 629 MARCOS ROBERTO | D4: -1105 | E4: 393911.87
A5: 02/01/2026 | B5: PIX ENVIADO 40 284 132 GUILHERME JUNI | D5: -888 | E5: 395016.87
A6: 02/01/2026 | B6: PAGAMENTO DE BOLETO OUTROS BANCOS LUZ PARA O CAMINHO | C6: 0000000000 | D6: -725 | E6: 395904.87
A7: 02/01/2026 | B7: PAGAMENTO DE BOLETO VIDA MELHOR EDI | C7: 0000000000 | D7: -4796.51 | E7: 396629.87
A8: 02/01/2026 | B8: PAGAMENTO DE BOLETO EDITORA HAGNOS | C8: 0000000000 | D8: -270.72 | E8: 401426.38
A9: 02/01/2026 | B9: PAGAMENTO DE BOLETO OUTROS BANCOS FLEXPACK INDUSTRIA E COME | C9: 0000000000 | D9: -3289.16 | E9: 401697.1
A10: 02/01/2026 | B10: PAGAMENTO DE BOLETO PORTO SEGURO - | C10: 0000000000 | D10: -1710.17 | E10: 404986.26
A11: 02/01/2026 | B11: PAGAMENTO DE BOLETO OUTROS BANCOS CONTABIL RIBEIRO LTDA | C11: 0000000000 | D11: -6505 | E11: 406696.43
A12: 05/01/2026 | B12: PIX ENVIADO 21 972 538 ABNER HENRIQUE | D12: -975.69 | E12: 418415.81
A13: 05/01/2026 | B13: PAGAMENTO DE BOLETO OUTROS BANCOS EDITORA HAGNOS LTDA | C13: 0000000000 | D13: -307.72 | E13: 419391.5
A14: 05/01/2026 | B14: PAGAMENTO DE BOLETO OUTROS BANCOS EMPRESA BRASILEIRA DE COR | C14: 0000000000 | D14: -5133.31 | E14: 419699.22
A15: 05/01/2026 | B15: PAGAMENTO DE BOLETO OUTROS BANCOS IPSIS GRAFICA E EDITORA S | C15: 0000000000 | D15: -14318.53 | E15: 424832.53
A16: 05/01/2026 | B16: PAGAMENTO DE BOLETO OUTROS BANCOS FLOWBIZ TECNOLOGIA DA INF | C16: 0000000000 | D16: -2178 | E16: 439151.06
A17: 05/01/2026 | B17: PAGAMENTO DE BOLETO OUTROS BANCOS IPSIS GRAFICA E EDITORA S | C17: 0000000000 | D17: -18475.52 | E17: 441329.06
A18: 05/01/2026 | B18: PAGAMENTO DE BOLETO OUTROS BANCOS EDITORA HAGNOS LTDA | C18: 0000000000 | D18: -1288.99 | E18: 459804.58
A19: 05/01/2026 | B19: PAGAMENTO DE BOLETO OUTROS BANCOS IPSIS GRAFICA E EDITORA S | C19: 0000000000 | D19: -12009.09 | E19: 461093.57
A20: 05/01/2026 | B20: PAGAMENTO DE BOLETO OUTROS BANCOS EDITORA HAGNOS LTDA | C20: 0000000000 | D20: -1586.1 | E20: 473102.66
A21: 05/01/2026 | B21: TED RECEBIDA 40804477000144 | D21: 25101.72 | E21: 474688.76
A22: 05/01/2026 | B22: PIX RECEBIDO 40804477000144 | D22: 28000 | E22: 449587.04
A23: 05/01/2026 | B23: PAGAMENTO CARTAO DE CREDITO AMAZON-VISA | C23: 0000477144 | D23: 4842.54 | E23: 421587.04
A24: 05/01/2026 | B24: PEDAGIO ELETRONICO - SEM PARAR SEM PARAR | D24: -64.74 | E24: 416744.5
A25: 05/01/2026 | B25: TARIFA AVULSA ENVIO PIX | D25: -5.78 | E25: 416809.24
A26: 05/01/2026 | B26: CR COB BLOQ COMP CONF RECEBIMENTO 0729/000028892 | D26: 3144.43 | E26: 416815.02
A27: 06/01/2026 | B27: RENDIMENTO LIQUIDO DE CONTAMAX 7000 RENDIMENTO LIQUIDO DE CONTAMAX | D27: 2.88 | E27: 387003.01
A28: 06/01/2026 | B28: TARIFA MANUTENCAO TIT VENCIDO | C28: 198927 | D28: -3.28 | E28: 387000.13
A29: 06/01/2026 | B29: PIX ENVIADO TO ON LOG | C29: 16593136 | D29: -579.9 | E29: 387003.41
A30: 06/01/2026 | B30: PAGAMENTO DE BOLETO OUTROS BANCOS SOC RELIGIOSA EDIC VIDA N | C30: 0000000000 | D30: -423.91 | E30: 387583.31
A31: 06/01/2026 | B31: PAGAMENTO DE BOLETO OUTROS BANCOS IPSIS GRAFICA E EDITORA S | C31: 0000000000 | D31: -16764.06 | E31: 388007.22
A32: 06/01/2026 | B32: PIX ENVIADO PNH TRAVEL | D32: -1454.62 | E32: 404771.28
A33: 06/01/2026 | B33: PIX ENVIADO EDUARDO MANO DE ANDRADE | D33: -2960 | E33: 406225.9
A34: 06/01/2026 | B34: PIX ENVIADO 21 972 538 ABNER HENRIQUE | D34: -960 | E34: 409185.9
A35: 06/01/2026 | B35: PIX ENVIADO CAMARA BRASILEIRA DO LIVR | D35: -27.4 | E35: 410145.9
A36: 06/01/2026 | B36: PAGAMENTO DE BOLETO QUALICORP ADMINISTRADORA | D36: -8242.51 | E36: 410173.3
A37: 07/01/2026 | B37: TAR BAIXA COB SIMPLES-ELETRONICA | C37: 198927 | D37: -1.84 | E37: 443661.86
A38: 07/01/2026 | B38: TAR LIQ COB COM REG COMPE | C38: 198927 | D38: -4.28 | E38: 443663.7
A39: 07/01/2026 | B39: PAGAMENTO DE BOLETO OUTROS BANCOS J V M I COMERCIO CAFE LTD | C39: 0000000000 | D39: -219.5 | E39: 443667.98
A40: 07/01/2026 | B40: PAGAMENTO DE BOLETO OUTROS BANCOS EDITORA HAGNOS LTDA | C40: 0000000000 | D40: -2891.32 | E40: 443887.48
...

Sheet literarius-santander
B1: Literárius | C1: Santander | D1: Diferença
A2: 46024 | B2: =SUMIF('extrato-literarius'!C:C,'literarius-santander'!A2,'extrato-literarius'!F:F) -> 469.16 | C2: =SUMIF('extrato-santander'!A:A,'literarius-santander'!A2,'extrato-santander'!D:D) -> 469.16 | D2: =B2-C2 -> 1.8189894e-12
A3: 46027 | B3: =SUMIF('extrato-literarius'!C:C,'literarius-santander'!A3,'extrato-literarius'!F:F) -> 4745.22 | C3: =SUMIF('extrato-santander'!A:A,'literarius-santander'!A3,'extrato-santander'!D:D) -> 4745.22 | D3: =B3-C3 -> 1.1823431e-11
A4: 46028 | B4: =SUMIF('extrato-literarius'!C:C,'literarius-santander'!A4,'extrato-literarius'!F:F) -> -31412.8 | C4: =SUMIF('extrato-santander'!A:A,'literarius-santander'!A4,'extrato-santander'!D:D) -> -31412.8 | D4: =B4-C4 -> 0
A5: 46029 | B5: =SUMIF('extrato-literarius'!C:C,'literarius-santander'!A5,'extrato-literarius'!F:F) -> 56658.85 | C5: =SUMIF('extrato-santander'!A:A,'literarius-santander'!A5,'extrato-santander'!D:D) -> 56658.85 | D5: =B5-C5 -> 0
A6: 46030 | B6: =SUMIF('extrato-literarius'!C:C,'literarius-santander'!A6,'extrato-literarius'!F:F) -> -8261.03 | C6: =SUMIF('extrato-santander'!A:A,'literarius-santander'!A6,'extrato-santander'!D:D) -> -8261.03 | D6: =B6-C6 -> 0
A7: 46031 | B7: =SUMIF('extrato-literarius'!C:C,'literarius-santander'!A7,'extrato-literarius'!F:F) -> -52394.57 | C7: =SUMIF('extrato-santander'!A:A,'literarius-santander'!A7,'extrato-santander'!D:D) -> -52394.57 | D7: =B7-C7 -> 0
A8: 46034 | B8: =SUMIF('extrato-literarius'!C:C,'literarius-santander'!A8,'extrato-literarius'!F:F) -> -88840.38 | C8: =SUMIF('extrato-santander'!A:A,'literarius-santander'!A8,'extrato-santander'!D:D) -> -88840.38 | D8: =B8-C8 -> 0
A9: 46035 | B9: =SUMIF('extrato-literarius'!C:C,'literarius-santander'!A9,'extrato-literarius'!F:F) -> -8868.13 | C9: =SUMIF('extrato-santander'!A:A,'literarius-santander'!A9,'extrato-santander'!D:D) -> -8868.13 | D9: =B9-C9 -> 0
A10: 46036 | B10: =SUMIF('extrato-literarius'!C:C,'literarius-santander'!A10,'extrato-literarius'!F:F) -> 17633.36 | C10: =SUMIF('extrato-santander'!A:A,'literarius-santander'!A10,'extrato-santander'!D:D) -> 17633.36 | D10: =B10-C10 -> 0
A11: 46037 | B11: =SUMIF('extrato-literarius'!C:C,'literarius-santander'!A11,'extrato-literarius'!F:F) -> -29225.33 | C11: =SUMIF('extrato-santander'!A:A,'literarius-santander'!A11,'extrato-santander'!D:D) -> -29225.33 | D11: =B11-C11 -> 0
A12: 46038 | B12: =SUMIF('extrato-literarius'!C:C,'literarius-santander'!A12,'extrato-literarius'!F:F) -> -25042.79 | C12: =SUMIF('extrato-santander'!A:A,'literarius-santander'!A12,'extrato-santander'!D:D) -> -25042.79 | D12: =B12-C12 -> 0
A13: 46041 | B13: =SUMIF('extrato-literarius'!C:C,'literarius-santander'!A13,'extrato-literarius'!F:F) -> 68431.13 | C13: =SUMIF('extrato-santander'!A:A,'literarius-santander'!A13,'extrato-santander'!D:D) -> 68431.13 | D13: =B13-C13 -> 0
... A22: 46052 | B22: =SUMIF('extrato-literarius'!C:C,'literarius-santander'!A22,'extrato-literarius'!F:F) -> -118921.51 | C22: =SUMIF('extrato-santander'!A:A,'literarius-santander'!A22,'extrato-santander'!D:D) -> -118921.51 | D22: =B22-C22 -> 0
