Workbook

Sheet extrato-stone-literarius
A1: Tipo | B1: Número | C1: Data | D1: Documento | E1: Descrição | F1: Valor | G1: Origem | H1: Plano de Contas | I1: Centro Resultados | J1: Conta Contábil
A2: C | B2: 2424 | C2: 01/01/2026 | D2: 2424 | E2: Recebimento vendas - AntecipaÃ | F2: 77 | G2: BANCÁRIO | H2: VENDA DE LIVROS | I2: Receita de vendas | J2: =VLOOKUP(H2,Planilha2!B:C,2,0) -> 132 a 134
A3: C | B3: 2425 | C3: 01/01/2026 | D3: 2425 | E3: Recebimento vendas - AntecipaÃ | F3: 32.38 | G3: BANCÁRIO | H3: VENDA DE LIVROS | I3: Receita de vendas | J3: =VLOOKUP(H3,Planilha2!B:C,2,0) -> 132 a 134
A4: C | B4: 2423 | C4: 02/01/2026 | D4: 2423 | E4: Recebimento vendas - AntecipaÃ | F4: 206.64 | G4: BANCÁRIO | H4: VENDA DE LIVROS | I4: Receita de vendas | J4: =VLOOKUP(H4,Planilha2!B:C,2,0) -> 132 a 134
A5: C | B5: 2370 | C5: 04/01/2026 | D5: 2370 | E5: Recebimento vendas - AntecipaÃ | F5: 51.11 | G5: BANCÁRIO | H5: VENDA DE LIVROS | I5: Receita de vendas | J5: =VLOOKUP(H5,Planilha2!B:C,2,0) -> 132 a 134
A6: C | B6: 2371 | C6: 04/01/2026 | D6: 2371 | E6: Recebimento vendas - AntecipaÃ | F6: 1004.37 | G6: BANCÁRIO | H6: VENDA DE LIVROS | I6: Receita de vendas | J6: =VLOOKUP(H6,Planilha2!B:C,2,0) -> 132 a 134
A7: C | B7: 2372 | C7: 04/01/2026 | D7: 2372 | E7: Recebimento vendas - AntecipaÃ | F7: 198.49 | G7: BANCÁRIO | H7: VENDA DE LIVROS | I7: Receita de vendas | J7: =VLOOKUP(H7,Planilha2!B:C,2,0) -> 132 a 134
A8: C | B8: 2373 | C8: 04/01/2026 | D8: 2373 | E8: Recebimento vendas - AntecipaÃ | F8: 340.36 | G8: BANCÁRIO | H8: VENDA DE LIVROS | I8: Receita de vendas | J8: =VLOOKUP(H8,Planilha2!B:C,2,0) -> 132 a 134
A9: C | B9: 2374 | C9: 04/01/2026 | D9: 2374 | E9: Recebimento vendas - AntecipaÃ | F9: 711.3 | G9: BANCÁRIO | H9: VENDA DE LIVROS | I9: Receita de vendas | J9: =VLOOKUP(H9,Planilha2!B:C,2,0) -> 132 a 134
A10: C | B10: 2375 | C10: 04/01/2026 | D10: 2375 | E10: Recebimento vendas - AntecipaÃ | F10: 86.51 | G10: BANCÁRIO | H10: VENDA DE LIVROS | I10: Receita de vendas | J10: =VLOOKUP(H10,Planilha2!B:C,2,0) -> 132 a 134
A11: C | B11: 2376 | C11: 04/01/2026 | D11: 2376 | E11: Recebimento vendas - AntecipaÃ | F11: 237.77 | G11: BANCÁRIO | H11: VENDA DE LIVROS | I11: Receita de vendas | J11: =VLOOKUP(H11,Planilha2!B:C,2,0) -> 132 a 134
A12: C | B12: 2377 | C12: 04/01/2026 | D12: 2377 | E12: Recebimento vendas - AntecipaÃ | F12: 355.46 | G12: BANCÁRIO | H12: VENDA DE LIVROS | I12: Receita de vendas | J12: =VLOOKUP(H12,Planilha2!B:C,2,0) -> 132 a 134
A13: C | B13: 2378 | C13: 04/01/2026 | D13: 2378 | E13: Recebimento vendas - AntecipaÃ | F13: 561.7 | G13: BANCÁRIO | H13: VENDA DE LIVROS | I13: Receita de vendas | J13: =VLOOKUP(H13,Planilha2!B:C,2,0) -> 132 a 134
... A399: C | B399: 2611 | C399: 31/01/2026 | D399: 2611 | E399: PEDRO ARTHUR FREITAS DIAS - Tr | F399: 1500 | G399: BANCÁRIO | H399: VENDA DE LIVROS | I399: Receita de vendas | J399: =VLOOKUP(H399,Planilha2!B:C,2,0) -> 132 a 134

Sheet Planilha2
A1: Codigo | B1: Descrição | C1: Contas contábeis
A2: 0 | B2: Cod 0561 | Cod 1082 | Cod 1138 | Cod 1170 | Cod 1176 | Cod 1191 | Cod 1196 | Cod 1200 | Cod 1646 | Cod 8301 | C2: 62
A3: 2 | B3: VENDA DE LIVROS | C3: 132 a 134
A4: 3 | B4: AQUISIÇÃO DE LIVROS | C4: 28
A5: 4 | B5: VENDA DE EBOOK | C5: 134
A6: 10 | B6: 13º Salário | C6: 180 a 192
A7: 11 | B7: Despesas Editorial - Capa | C7: 752
A8: 12 | B8: Despesas Editorial - Conferência de Emendas | Despesas Editorial - Revisão de Prova | C8: 752
A9: 13 | B9: Despesas Editorial - Diagramação | C9: 185
A10: 14 | B10: Despesas Editorial - Edição | C10: 185
A11: 15 | B11: Despesas Editorial - Ilustração | C11: 752
A12: 16 | B12: Despesas Editorial - Preparação | C12: 752
A13: 17 | B13: Despesas Editorial - Produção Editorial | C13: 752
A14: 18 | B14: Despesas Editorial - Revisão de Prova | C14: 752
A15: 19 | B15: Despesas Editorial - Tradução | C15: 752
A16: 20 | B16: Materiais Para Revenda | C16: 80
A17: 21 | B17: Producao Material Proprio | C17: 80
A18: 21 | B18: Produção Material Próprio | C18: 80
... A75: 77 | B75: Impostos E Taxas | C75: 225
A76: 78 | B76: Estorno e Reembolso | C76: 231 LANÇAR NA NATUREZA DA DESPESA
A77: 79 | B77: Internet | C77: 233
A78: 80 | B78: Monitoramento Sede | C78: 67
A79: 81 | B79: Royalties | C79: 165
A80: 82 | B80: PIS 8301 | C80: 197
A81: 83 | B81: Terreno e Dependências - Sede | C81: 255
A82: 84 | B82: Sistemas e Softwares -Adm Marketing | C82: 244
A83: 85 | B83: Sistemas e Softwares Comerciais | C83: 710
A84: 86 | B84: Devolução de Venda | C84: 166
A85: 87 | B85: Exames médicos | C85: 193
A86: 88 | B86: Juros pagos/passivos | C86: 251
A87: 89 | B87: Lanches e Refeições Equipe | C87: 215
A88: 90 | B88: Lanches e Refeições Comercial | C88: 212
... A99: 101 | B99: Condomínio | C99: 237
A100: 102 | B100: DESPESAS OPERACIONAIS | C100: 4.3.1
A101: 103 | B101: DESPESAS ADMINISTRATIVAS | C101: 4.3.1.01
A102: 104 | B102: Materiais Impressos | C102: 224
A103: 105 | B103: Cod 0561 | C103: 67
A104: 106 | B104: TRANSFERENCIA ENTRE CONTAS | C104: 0
A105: 107 | B105: Despesas Bancárias | C105: 252
A106: 108 | B106: Rescisões | C106: 188 A 192
...

Sheet extrato stone
A1: Movimentação | B1: Tipo | C1: Valor | D1: Tarifa | F1: Saldo antes | G1: Saldo depois | H1: Data | J1: Nosso Número | K1: Situação | L1: Destino | M1: Destino Documento | N1: Destino Instituição | O1: Destino Agência | P1: Destino Conta | Q1: Origem | R1: Origem Documento | S1: Origem Instituição | T1: Origem Agência | U1: Origem Conta
A2: Crédito | B2: Transferência entre contas Stone | C2: 77,00 | D2: R$ 0,00 | E2: =C2-D2 -> 77 | F2: R$ 10.054,83 | G2: R$ 10.131,83 | H2: 01/01/2026 03:13 | I2: 46023 | K2: Recebida | L2: Editora Heziom | M2: 40.804.477/0001-44 | N2: Stone Instituição de Pagamento S.A. | O2: 0001 | P2: 890291-8 | Q2: Stone Principal | R2: 16.501.555/0001-57 | S2: STONE INSTITUIÇÃO DE PAGAMENTO S.A. | T2: 0001 | U2: 30772-8
A3: Crédito | B3: Transferência entre contas Stone | C3: 32,38 | D3: R$ 0,00 | E3: =C3-D3 -> 32.38 | F3: R$ 10.022,45 | G3: R$ 10.054,83 | H3: 01/01/2026 03:13 | I3: 46023 | K3: Recebida | L3: Editora Heziom | M3: 40.804.477/0001-44 | N3: Stone Instituição de Pagamento S.A. | O3: 0001 | P3: 890291-8 | Q3: Stone Principal | R3: 16.501.555/0001-57 | S3: STONE INSTITUIÇÃO DE PAGAMENTO S.A. | T3: 0001 | U3: 30772-8
A4: Crédito | B4: Transferência entre contas Stone | C4: 206,64 | D4: R$ 0,00 | E4: =C4-D4 -> 206.64 | F4: R$ 10.131,83 | G4: R$ 10.338,47 | H4: 02/01/2026 13:29 | I4: 46024 | K4: Recebida | L4: Editora Heziom | M4: 40.804.477/0001-44 | N4: Stone Instituição de Pagamento S.A. | O4: 0001 | P4: 890291-8 | Q4: Stone Principal | R4: 16.501.555/0001-57 | S4: STONE INSTITUIÇÃO DE PAGAMENTO S.A. | T4: 0001 | U4: 30772-8
A5: Crédito | B5: Transação | C5: 30,00 | D5: R$ 0,15 | E5: =C5-D5 -> 29.85 | F5: R$ 10.338,47 | G5: R$ 10.368,32 | H5: 04/01/2026 07:43 | I5: 46026 | K5: FINISHED | L5: Editora Heziom | M5: 40.804.477/0001-44 | N5: Stone Instituição de Pagamento S.A. | O5: 0001 | P5: 890291-8 | Q5: GLEYCE ROSA SILVA SANTOS | R5: ***.897.771-** | S5: Banco do Brasil S.A. | T5: Desconhecido | U5: Desconhecido
A6: Crédito | B6: Transferência entre contas Stone | C6: 76,54 | D6: R$ 0,00 | E6: =C6-D6 -> 76.54 | F6: R$ 10.550,90 | G6: R$ 10.627,44 | H6: 04/01/2026 09:12 | I6: 46026 | K6: Recebida | L6: Editora Heziom | M6: 40.804.477/0001-44 | N6: Stone Instituição de Pagamento S.A. | O6: 0001 | P6: 890291-8 | Q6: Stone Principal | R6: 16.501.555/0001-57 | S6: STONE INSTITUIÇÃO DE PAGAMENTO S.A. | T6: 0001 | U6: 30772-8
A7: Crédito | B7: Transferência entre contas Stone | C7: 182,58 | D7: R$ 0,00 | E7: =C7-D7 -> 182.58 | F7: R$ 10.368,32 | G7: R$ 10.550,90 | H7: 04/01/2026 09:12 | I7: 46026 | K7: Recebida | L7: Editora Heziom | M7: 40.804.477/0001-44 | N7: Stone Instituição de Pagamento S.A. | O7: 0001 | P7: 890291-8 | Q7: Stone Principal | R7: 16.501.555/0001-57 | S7: STONE INSTITUIÇÃO DE PAGAMENTO S.A. | T7: 0001 | U7: 30772-8
A8: Crédito | B8: Transação | C8: 215,80 | D8: R$ 1,07 | E8: =C8-D8 -> 214.73 | F8: R$ 10.627,44 | G8: R$ 10.842,17 | H8: 04/01/2026 09:25 | I8: 46026 | K8: FINISHED | L8: Editora Heziom | M8: 40.804.477/0001-44 | N8: Stone Instituição de Pagamento S.A. | O8: 0001 | P8: 890291-8 | Q8: RAQUEL MARCHIORI LESSA DE AZEVEDO | R8: ***.507.724-** | S8: 99PAY INSTITUICAO DE PAGAMENTO S.A. | T8: Desconhecido | U8: Desconhecido
A9: Crédito | B9: Transação | C9: 159,80 | D9: R$ 0,79 | E9: =C9-D9 -> 159.01 | F9: R$ 10.842,17 | G9: R$ 11.001,18 | H9: 04/01/2026 09:43 | I9: 46026 | K9: FINISHED | L9: Editora Heziom | M9: 40.804.477/0001-44 | N9: Stone Instituição de Pagamento S.A. | O9: 0001 | P9: 890291-8 | Q9: JULIANA DA ROCHA MIRANDA | R9: ***.256.282-** | S9: ITAÚ UNIBANCO S.A. | T9: Desconhecido | U9: Desconhecido
A10: Crédito | B10: Transação | C10: 222,02 | D10: R$ 1,11 | E10: =C10-D10 -> 220.91 | F10: R$ 11.001,18 | G10: R$ 11.222,09 | H10: 04/01/2026 10:31 | I10: 46026 | K10: FINISHED | L10: Editora Heziom | M10: 40.804.477/0001-44 | N10: Stone Instituição de Pagamento S.A. | O10: 0001 | P10: 890291-8 | Q10: JEFERSON APARECIDO PEREIRA DE ANDRADE | R10: ***.358.698-** | S10: COOPERATIVA DE CRÉDITO COOPACREDI LTDA. - SICOOB COOPACREDI | T10: Desconhecido | U10: Desconhecido
A11: Crédito | B11: Transação | C11: 129,36 | D11: R$ 0,64 | E11: =C11-D11 -> 128.72 | F11: R$ 11.222,09 | G11: R$ 11.350,81 | H11: 04/01/2026 10:34 | I11: 46026 | K11: FINISHED | L11: Editora Heziom | M11: 40.804.477/0001-44 | N11: Stone Instituição de Pagamento S.A. | O11: 0001 | P11: 890291-8 | Q11: PRISCYLA K PROENCA DE ARAUJO | R11: ***.243.608-** | S11: ITAÚ UNIBANCO S.A. | T11: Desconhecido | U11: Desconhecido
A12: Crédito | B12: Transação | C12: 149,90 | D12: R$ 0,74 | E12: =C12-D12 -> 149.16 | F12: R$ 11.350,81 | G12: R$ 11.499,97 | H12: 04/01/2026 10:36 | I12: 46026 | K12: FINISHED | L12: Editora Heziom | M12: 40.804.477/0001-44 | N12: Stone Instituição de Pagamento S.A. | O12: 0001 | P12: 890291-8 | Q12: Luciane da Silva | R12: ***.904.738-** | S12: MERCADO PAGO INSTITUIÇÃO DE PAGAMENTO LTDA. | T12: Desconhecido | U12: Desconhecido
A13: Crédito | B13: Transação | C13: 84,90 | D13: R$ 0,42 | E13: =C13-D13 -> 84.48 | F13: R$ 11.499,97 | G13: R$ 11.584,45 | H13: 04/01/2026 10:50 | I13: 46026 | K13: FINISHED | L13: Editora Heziom | M13: 40.804.477/0001-44 | N13: Stone Instituição de Pagamento S.A. | O13: 0001 | P13: 890291-8 | Q13: CAMILA PRADO SANTOS | R13: ***.094.681-** | S13: Banco Inter S.A. | T13: Desconhecido | U13: Desconhecido
... A57: Crédito | B57: Transferência entre contas Stone | C57: 711,30 | D57: R$ 0,00 | E57: =C57-D57 -> 711.3 | F57: R$ 23.999,68 | G57: R$ 24.710,98 | H57: 04/01/2026 23:11 | I57: 46026 | K57: Recebida | L57: Editora Heziom | M57: 40.804.477/0001-44 | N57: Stone Instituição de Pagamento S.A. | O57: 0001 | P57: 890291-8 | Q57: Stone Principal | R57: 16.501.555/0001-57 | S57: STONE INSTITUIÇÃO DE PAGAMENTO S.A. | T57: 0001 | U57: 30772-8
A58: Crédito | B58: Pix | C58: 1.018,30 | D58: 0 | E58: =C58-D58 -> 1018.3 | F58: R$ 26.305,31 | G58: R$ 27.323,61 | H58: 05/01/2026 12:13 | I58: 46027 | K58: Recebido | L58: Editora Heziom | M58: 40.804.477/0001-44 | N58: Stone Instituição de Pagamento S.A. | O58: 0001 | P58: 890291-8 | Q58: Débora Vanessa Mariano | R58: ***.978.996-** | S58: Banco BTG Pactual S.A. | T58: Desconhecido | U58: Desconhecido
A59: Crédito | B59: Pix | C59: 1.497,50 | D59: 0 | E59: =C59-D59 -> 1497.5 | F59: R$ 27.323,61 | G59: R$ 28.821,11 | H59: 05/01/2026 13:00 | I59: 46027 | K59: Recebido | L59: Editora Heziom | M59: 40.804.477/0001-44 | N59: Stone Instituição de Pagamento S.A. | O59: 0001 | P59: 890291-8 | Q59: IANNA ROSA LUCAS TORRES | R59: ***.299.321-** | S59: Banco XP S.A. | T59: Desconhecido | U59: Desconhecido
A60: Crédito | B60: Pix | C60: 419,30 | D60: 0 | E60: =C60-D60 -> 419.3 | F60: R$ 28.821,11 | G60: R$ 29.240,41 | H60: 05/01/2026 13:09 | I60: 46027 | K60: Recebido | L60: Editora Heziom | M60: 40.804.477/0001-44 | N60: Stone Instituição de Pagamento S.A. | O60: 0001 | P60: 890291-8 | Q60: Glaucilene Campos Figueredo | R60: ***.406.691-** | S60: NU PAGAMENTOS S.A. - INSTITUIÇÃO DE PAGAMENTO | T60: Desconhecido | U60: Desconhecido
A61: Crédito | B61: Pix | C61: 1.500,00 | D61: 0 | E61: =C61-D61 -> 1500 | F61: R$ 29.240,41 | G61: R$ 30.740,41 | H61: 05/01/2026 13:53 | I61: 46027 | K61: Recebido | L61: Editora Heziom | M61: 40.804.477/0001-44 | N61: Stone Instituição de Pagamento S.A. | O61: 0001 | P61: 890291-8 | Q61: IGREJA P NACIONAL | R61: 00.096.388/0001-76 | S61: Banco do Brasil S.A. | T61: Desconhecido | U61: Desconhecido
A62: Crédito | B62: Pix | C62: 61,05 | D62: 0 | E62: =C62-D62 -> 61.05 | F62: R$ 30.740,41 | G62: R$ 30.801,46 | H62: 05/01/2026 14:44 | I62: 46027 | K62: Recebido | L62: Editora Heziom | M62: 40.804.477/0001-44 | N62: Stone Instituição de Pagamento S.A. | O62: 0001 | P62: 890291-8 | Q62: JOCELI CARVALHO A FERREIRA | R62: ***.341.778-** | S62: ITAÚ UNIBANCO S.A. | T62: Desconhecido | U62: Desconhecido
A63: Crédito | B63: Transferência entre contas Stone | C63: 49,38 | D63: R$ 0,00 | E63: =C63-D63 -> 49.38 | F63: R$ 30.801,46 | G63: R$ 30.850,84 | H63: 05/01/2026 15:18 | I63: 46027 | K63: Recebida | L63: Editora Heziom | M63: 40.804.477/0001-44 | N63: Stone Instituição de Pagamento S.A. | O63: 0001 | P63: 890291-8 | Q63: Stone Principal | R63: 16.501.555/0001-57 | S63: STONE INSTITUIÇÃO DE PAGAMENTO S.A. | T63: 0001 | U63: 30772-8
A64: Crédito | B64: Pix | C64: 718,80 | D64: 0 | E64: =C64-D64 -> 718.8 | F64: R$ 30.850,84 | G64: R$ 31.569,64 | H64: 05/01/2026 15:26 | I64: 46027 | K64: Recebido | L64: Editora Heziom | M64: 40.804.477/0001-44 | N64: Stone Instituição de Pagamento S.A. | O64: 0001 | P64: 890291-8 | Q64: HERMELINDA COSTA SARAIVA | R64: ***.814.391-** | S64: CAIXA ECONOMICA FEDERAL | T64: Desconhecido | U64: Desconhecido
A65: Débito | B65: Pix | C65: -104,40 | D65: 0 | E65: =C65-D65 -> -104.4 | F65: R$ 31.569,64 | G65: R$ 31.465,24 | H65: 05/01/2026 15:42 | I65: 46027 | K65: Enviado | L65: ANA MARIA NEVES SAC ZECHMANN | M65: ***.943.138-** | N65: Banco C6 S.A. | O65: Desconhecido | P65: Desconhecido | Q65: Editora Heziom | R65: 40.804.477/0001-44 | S65: Stone Instituição de Pagamento S.A. | T65: 0001 | U65: 890291-8
A66: Débito | B66: Pix | C66: -50,00 | D66: 0 | E66: =C66-D66 -> -50 | F66: R$ 32.004,34 | G66: R$ 31.954,34 | H66: 05/01/2026 15:43 | I66: 46027 | K66: Enviado | L66: Rafael Pereira Barbosa | M66: ***.248.848-** | N66: NU PAGAMENTOS S.A. - INSTITUIÇÃO DE PAGAMENTO | O66: Desconhecido | P66: Desconhecido | Q66: Editora Heziom | R66: 40.804.477/0001-44 | S66: Stone Instituição de Pagamento S.A. | T66: 0001 | U66: 890291-8
A67: Crédito | B67: Pix | C67: 539,10 | D67: 0 | E67: =C67-D67 -> 539.1 | F67: R$ 31.465,24 | G67: R$ 32.004,34 | H67: 05/01/2026 15:43 | I67: 46027 | K67: Recebido | L67: Editora Heziom | M67: 40.804.477/0001-44 | N67: Stone Instituição de Pagamento S.A. | O67: 0001 | P67: 890291-8 | Q67: Maria Cristina Soares Dias Ribeiro | R67: ***.651.541-** | S67: NU PAGAMENTOS S.A. - INSTITUIÇÃO DE PAGAMENTO | T67: Desconhecido | U67: Desconhecido
A68: Débito | B68: Pix | C68: -28.000,00 | D68: 0 | E68: =C68-D68 -> -28000 | F68: R$ 31.954,34 | G68: R$ 3.954,34 | H68: 05/01/2026 15:44 | I68: 46027 | K68: Enviado | L68: ASSOCIACAO EDITORA PRESBITERIANA DE PINHEIROS | M68: 40.804.477/0001-44 | N68: BANCO SANTANDER (BRASIL) S.A. | O68: Desconhecido | P68: Desconhecido | Q68: Editora Heziom | R68: 40.804.477/0001-44 | S68: Stone Instituição de Pagamento S.A. | T68: 0001 | U68: 890291-8
A69: Crédito | B69: Pix | C69: 958,40 | D69: 0 | E69: =C69-D69 -> 958.4 | F69: R$ 3.954,34 | G69: R$ 4.912,74 | H69: 05/01/2026 15:49 | I69: 46027 | K69: Recebido | L69: Editora Heziom | M69: 40.804.477/0001-44 | N69: Stone Instituição de Pagamento S.A. | O69: 0001 | P69: 890291-8 | Q69: GLAUCIA STELA DE CASTRO ROCHA | R69: ***.560.561-** | S69: PICPAY INSTITUIçãO DE PAGAMENTO S.A. | T69: Desconhecido | U69: Desconhecido
A70: Crédito | B70: Pix | C70: 86,42 | D70: 0 | E70: =C70-D70 -> 86.42 | F70: R$ 4.912,74 | G70: R$ 4.999,16 | H70: 05/01/2026 15:56 | I70: 46027 | K70: Recebido | L70: Editora Heziom | M70: 40.804.477/0001-44 | N70: Stone Instituição de Pagamento S.A. | O70: 0001 | P70: 890291-8 | Q70: IGREJA P NACIONAL | R70: 00.096.388/0001-76 | S70: Banco do Brasil S.A. | T70: Desconhecido | U70: Desconhecido
A71: Crédito | B71: Transação | C71: 41,93 | D71: R$ 0,20 | E71: =C71-D71 -> 41.73 | F71: R$ 4.999,16 | G71: R$ 5.040,89 | H71: 05/01/2026 16:35 | I71: 46027 | K71: FINISHED | L71: Editora Heziom | M71: 40.804.477/0001-44 | N71: Stone Instituição de Pagamento S.A. | O71: 0001 | P71: 890291-8 | Q71: DIEGO M GALHARDO | R71: ***.818.118-** | S71: Banco Bradesco S.A. | T71: Desconhecido | U71: Desconhecido
A72: Crédito | B72: Transferência entre contas Stone | C72: 80,20 | D72: R$ 0,00 | E72: =C72-D72 -> 80.2 | F72: R$ 5.040,89 | G72: R$ 5.121,09 | H72: 05/01/2026 17:09 | I72: 46027 | K72: Recebida | L72: Editora Heziom | M72: 40.804.477/0001-44 | N72: Stone Instituição de Pagamento S.A. | O72: 0001 | P72: 890291-8 | Q72: Stone Principal | R72: 16.501.555/0001-57 | S72: STONE INSTITUIÇÃO DE PAGAMENTO S.A. | T72: 0001 | U72: 30772-8
A73: Crédito | B73: Transferência entre contas Stone | C73: 234,97 | D73: R$ 0,00 | E73: =C73-D73 -> 234.97 | F73: R$ 5.148,60 | G73: R$ 5.383,57 | H73: 05/01/2026 19:23 | I73: 46027 | K73: Recebida | L73: Editora Heziom | M73: 40.804.477/0001-44 | N73: Stone Instituição de Pagamento S.A. | O73: 0001 | P73: 890291-8 | Q73: Stone Principal | R73: 16.501.555/0001-57 | S73: STONE INSTITUIÇÃO DE PAGAMENTO S.A. | T73: 0001 | U73: 30772-8
A74: Crédito | B74: Transferência entre contas Stone | C74: 27,51 | D74: R$ 0,00 | E74: =C74-D74 -> 27.51 | F74: R$ 5.121,09 | G74: R$ 5.148,60 | H74: 05/01/2026 19:23 | I74: 46027 | K74: Recebida | L74: Editora Heziom | M74: 40.804.477/0001-44 | N74: Stone Instituição de Pagamento S.A. | O74: 0001 | P74: 890291-8 | Q74: Stone Principal | R74: 16.501.555/0001-57 | S74: STONE INSTITUIÇÃO DE PAGAMENTO S.A. | T74: 0001 | U74: 30772-8
A75: Crédito | B75: Pix | C75: 172,53 | D75: 0 | E75: =C75-D75 -> 172.53 | F75: R$ 5.383,57 | G75: R$ 5.556,10 | H75: 06/01/2026 11:49 | I75: 46028 | K75: Recebido | L75: Editora Heziom | M75: 40.804.477/0001-44 | N75: Stone Instituição de Pagamento S.A. | O75: 0001 | P75: 890291-8 | Q75: PATRICIA REGINA BARRETO LEITE | R75: ***.822.733-** | S75: CAIXA ECONOMICA FEDERAL | T75: Desconhecido | U75: Desconhecido
A76: Crédito | B76: Pix | C76: 9.887,92 | D76: 0 | E76: =C76-D76 -> 9887.92 | F76: R$ 5.556,10 | G76: R$ 15.444,02 | H76: 06/01/2026 11:56 | I76: 46028 | K76: Recebido | L76: Editora Heziom | M76: 40.804.477/0001-44 | N76: Stone Instituição de Pagamento S.A. | O76: 0001 | P76: 890291-8 | Q76: NEUSA FERNANDA BERNARDO ROSA | R76: ***.386.349-** | S76: CAIXA ECONOMICA FEDERAL | T76: Desconhecido | U76: Desconhecido
A77: Crédito | B77: Pix | C77: 1.377,70 | D77: 0 | E77: =C77-D77 -> 1377.7 | F77: R$ 15.444,02 | G77: R$ 16.821,72 | H77: 06/01/2026 12:38 | I77: 46028 | K77: Recebido | L77: Editora Heziom | M77: 40.804.477/0001-44 | N77: Stone Instituição de Pagamento S.A. | O77: 0001 | P77: 890291-8 | Q77: ELZA DE FATIMA SILVA | R77: ***.468.856-** | S77: Banco do Brasil S.A. | T77: Desconhecido | U77: Desconhecido
A78: Crédito | B78: Pix | C78: 6.682,54 | D78: 0 | E78: =C78-D78 -> 6682.54 | F78: R$ 16.821,72 | G78: R$ 23.504,26 | H78: 06/01/2026 16:00 | I78: 46028 | K78: Recebido | L78: Editora Heziom | M78: 40.804.477/0001-44 | N78: Stone Instituição de Pagamento S.A. | O78: 0001 | P78: 890291-8 | Q78: JOSE GONCALVES OLIVEIRA | R78: 630..-011 | S78: Banco do Brasil S.A. | T78: Desconhecido | U78: Desconhecido
A79: Crédito | B79: Pix | C79: 3.619,55 | D79: 0 | E79: =C79-D79 -> 3619.55 | F79: R$ 23.504,26 | G79: R$ 27.123,81 | H79: 06/01/2026 18:18 | I79: 46028 | K79: Recebido | L79: Editora Heziom | M79: 40.804.477/0001-44 | N79: Stone Instituição de Pagamento S.A. | O79: 0001 | P79: 890291-8 | Q79: Maria Emília de Almeida | R79: ***.844.101-** | S79: NU PAGAMENTOS S.A. - INSTITUIÇÃO DE PAGAMENTO | T79: Desconhecido | U79: Desconhecido
A80: Crédito | B80: Pix | C80: 2.237,54 | D80: 0 | E80: =C80-D80 -> 2237.54 | F80: R$ 27.123,81 | G80: R$ 29.361,35 | H80: 07/01/2026 10:22 | I80: 46029 | K80: Recebido | L80: Editora Heziom | M80: 40.804.477/0001-44 | N80: Stone Instituição de Pagamento S.A. | O80: 0001 | P80: 890291-8 | Q80: ANA MARIA ARRUDA OLIVEIRA | R80: ***.166.331-** | S80: CAIXA ECONOMICA FEDERAL | T80: Desconhecido | U80: Desconhecido
A81: Débito | B81: Pix | C81: -25.000,00 | D81: 0 | E81: =C81-D81 -> -25000 | F81: R$ 29.361,35 | G81: R$ 4.361,35 | H81: 07/01/2026 10:23 | I81: 46029 | K81: Enviado | L81: ASSOCIACAO EDITORA PRESBITERIANA DE PINHEIROS | M81: 40.804.477/0001-44 | N81: BANCO SANTANDER (BRASIL) S.A. | O81: Desconhecido | P81: Desconhecido | Q81: Editora Heziom | R81: 40.804.477/0001-44 | S81: Stone Instituição de Pagamento S.A. | T81: 0001 | U81: 890291-8
A82: Crédito | B82: Pix | C82: 105,50 | D82: 0 | E82: =C82-D82 -> 105.5 | F82: R$ 4.361,35 | G82: R$ 4.466,85 | H82: 07/01/2026 10:38 | I82: 46029 | K82: Recebido | L82: Editora Heziom | M82: 40.804.477/0001-44 | N82: Stone Instituição de Pagamento S.A. | O82: 0001 | P82: 890291-8 | Q82: IANNA ROSA LUCAS TORRES | R82: ***.299.321-** | S82: Banco XP S.A. | T82: Desconhecido | U82: Desconhecido
A83: Crédito | B83: Pix | C83: 67,52 | D83: 0 | E83: =C83-D83 -> 67.52 | F83: R$ 4.466,85 | G83: R$ 4.534,37 | H83: 07/01/2026 11:53 | I83: 46029 | K83: Recebido | L83: Editora Heziom | M83: 40.804.477/0001-44 | N83: Stone Instituição de Pagamento S.A. | O83: 0001 | P83: 890291-8 | Q83: GLAUCIA STELA DE CASTRO ROCHA | R83: ***.560.561-** | S83: PICPAY INSTITUIçãO DE PAGAMENTO S.A. | T83: Desconhecido | U83: Desconhecido
...

Sheet Planilha1
A1: Data | B1: Literarius | C1: Stone | D1: Diferença
A2: 46023 | B2: =SUMIF('extrato-stone-literarius'!C:C,Planilha1!A2,'extrato-stone-literarius'!F:F) -> 109.38 | C2: =SUMIF('extrato stone'!I:I,Planilha1!A2,'extrato stone'!E:E) -> 109.38 | D2: =B2-C2 -> 0
A3: 46024 | B3: =SUMIF('extrato-stone-literarius'!C:C,Planilha1!A3,'extrato-stone-literarius'!F:F) -> 206.64 | C3: =SUMIF('extrato stone'!I:I,Planilha1!A3,'extrato stone'!E:E) -> 206.64 | D3: =B3-C3 -> 0
A4: 46026 | B4: =SUMIF('extrato-stone-literarius'!C:C,Planilha1!A4,'extrato-stone-literarius'!F:F) -> 15966.84 | C4: =SUMIF('extrato stone'!I:I,Planilha1!A4,'extrato stone'!E:E) -> 15966.84 | D4: =B4-C4 -> 0
A5: 46027 | B5: =SUMIF('extrato-stone-literarius'!C:C,Planilha1!A5,'extrato-stone-literarius'!F:F) -> -20921.74 | C5: =SUMIF('extrato stone'!I:I,Planilha1!A5,'extrato stone'!E:E) -> -20921.74 | D5: =B5-C5 -> 0
A6: 46028 | B6: =SUMIF('extrato-stone-literarius'!C:C,Planilha1!A6,'extrato-stone-literarius'!F:F) -> 21740.24 | C6: =SUMIF('extrato stone'!I:I,Planilha1!A6,'extrato stone'!E:E) -> 21740.24 | D6: =B6-C6 -> 0
A7: 46029 | B7: =SUMIF('extrato-stone-literarius'!C:C,Planilha1!A7,'extrato-stone-literarius'!F:F) -> -22402.57 | C7: =SUMIF('extrato stone'!I:I,Planilha1!A7,'extrato stone'!E:E) -> -22402.57 | D7: =B7-C7 -> 0
A8: 46030 | B8: =SUMIF('extrato-stone-literarius'!C:C,Planilha1!A8,'extrato-stone-literarius'!F:F) -> 1096.37 | C8: =SUMIF('extrato stone'!I:I,Planilha1!A8,'extrato stone'!E:E) -> 1096.37 | D8: =B8-C8 -> 0
A9: 46031 | B9: =SUMIF('extrato-stone-literarius'!C:C,Planilha1!A9,'extrato-stone-literarius'!F:F) -> -1000 | C9: =SUMIF('extrato stone'!I:I,Planilha1!A9,'extrato stone'!E:E) -> -1000 | D9: =B9-C9 -> 0
A10: 46032 | B10: =SUMIF('extrato-stone-literarius'!C:C,Planilha1!A10,'extrato-stone-literarius'!F:F) -> 6738.92 | C10: =SUMIF('extrato stone'!I:I,Planilha1!A10,'extrato stone'!E:E) -> 6738.92 | D10: =B10-C10 -> 0
A11: 46033 | B11: =SUMIF('extrato-stone-literarius'!C:C,Planilha1!A11,'extrato-stone-literarius'!F:F) -> 15355.69 | C11: =SUMIF('extrato stone'!I:I,Planilha1!A11,'extrato stone'!E:E) -> 15355.69 | D11: =B11-C11 -> 0
A12: 46034 | B12: =SUMIF('extrato-stone-literarius'!C:C,Planilha1!A12,'extrato-stone-literarius'!F:F) -> 11085.54 | C12: =SUMIF('extrato stone'!I:I,Planilha1!A12,'extrato stone'!E:E) -> 11085.54 | D12: =B12-C12 -> 0
A13: 46035 | B13: =SUMIF('extrato-stone-literarius'!C:C,Planilha1!A13,'extrato-stone-literarius'!F:F) -> 9351.51 | C13: =SUMIF('extrato stone'!I:I,Planilha1!A13,'extrato stone'!E:E) -> 9351.51 | D13: =B13-C13 -> 0
... A29: 46053 | B29: =SUMIF('extrato-stone-literarius'!C:C,Planilha1!A29,'extrato-stone-literarius'!F:F) -> 2178.5 | C29: =SUMIF('extrato stone'!I:I,Planilha1!A29,'extrato stone'!E:E) -> 2178.5 | D29: =B29-C29 -> 0
