Workbook

Sheet Fluxo CC 7369
A1: Número | B1: Documento | C1: Valor | D1: Plano de Contas | E1: Centro Resultados | F1: Conta Contábil
A2: 33739 | B2: 33739 | C2: -208,68 | D2: Despesas Eventos Externos | E2: Administrativo | F2: =VLOOKUP('Fluxo CC 7369'!D2,Planilha1!B:C,2,0) -> 247
A3: 33740 | B3: 33740 | C3: -1.587,75 | D3: Cursos E Treinamentos | E3: Administrativo | F3: =VLOOKUP('Fluxo CC 7369'!D3,Planilha1!B:C,2,0) -> 211
A4: 33741 | B4: 33741 | C4: -166,41 | D4: Cursos E Treinamentos | E4: Administrativo | F4: =VLOOKUP('Fluxo CC 7369'!D4,Planilha1!B:C,2,0) -> 211
A5: 33742 | B5: 33742 | C5: -194,92 | D5: Sistemas e Softwares -Adm Marketing | E5: CPC Online | F5: =VLOOKUP('Fluxo CC 7369'!D5,Planilha1!B:C,2,0) -> 244
A6: 33743 | B6: 33743 | C6: -35,12 | D6: Despesas Custos Eventos | E6: Evento | F6: =VLOOKUP('Fluxo CC 7369'!D6,Planilha1!B:C,2,0) -> 247
A7: 33744 | B7: 33744 | C7: -380,66 | D7: Materiais Aplicados Venda Prod | E7: Expedição | F7: =VLOOKUP('Fluxo CC 7369'!D7,Planilha1!B:C,2,0) -> 224
A8: 33745 | B8: 33745 | C8: -1759.09 | D8: Marketing E Publicidade | E8: CPC Online | F8: =VLOOKUP('Fluxo CC 7369'!D8,Planilha1!B:C,2,0) -> 245
A9: 33746 | B9: 33746 | C9: -63.14 | D9: Materiais de Escritório | E9: Expedição | F9: =VLOOKUP('Fluxo CC 7369'!D9,Planilha1!B:C,2,0) -> 227
A10: 33747 | B10: 33747 | C10: -2006.22 | D10: Marketing E Publicidade | E10: CPC Online | F10: =VLOOKUP('Fluxo CC 7369'!D10,Planilha1!B:C,2,0) -> 245
A11: 33748 | B11: 33748 | C11: -548.34 | D11: Móveis, Máquinas e Utensílios | E11: Administrativo | F11: =VLOOKUP('Fluxo CC 7369'!D11,Planilha1!B:C,2,0) -> 41
A12: 33749 | B12: 33749 | C12: -99 | D12: Sistemas e Softwares Comerciais | E12: CPC Offline | F12: =VLOOKUP('Fluxo CC 7369'!D12,Planilha1!B:C,2,0) -> 710
A13: 33750 | B13: 33750 | C13: -434.34 | D13: Marketing E Publicidade | E13: CPC Online | F13: =VLOOKUP('Fluxo CC 7369'!D13,Planilha1!B:C,2,0) -> 245
A14: 33751 | B14: 33751 | C14: -1000 | D14: Frete Sobre Mercadorias | E14: Expedição | F14: =VLOOKUP('Fluxo CC 7369'!D14,Planilha1!B:C,2,0) -> 164
A15: 33752 | B15: 33752 | C15: -31.2 | D15: Frete Sobre Mercadorias | E15: Expedição | F15: =VLOOKUP('Fluxo CC 7369'!D15,Planilha1!B:C,2,0) -> 164
A16: 33753 | B16: 33753 | C16: -22.41 | D16: Materiais de Escritório | E16: Financeiro | F16: =VLOOKUP('Fluxo CC 7369'!D16,Planilha1!B:C,2,0) -> 227
A17: 33754 | B17: 33754 | C17: -36.14 | D17: Materiais de Escritório | E17: Financeiro | F17: =VLOOKUP('Fluxo CC 7369'!D17,Planilha1!B:C,2,0) -> 227
A18: 33755 | B18: 33755 | C18: -66.99 | D18: Materiais de Escritório | E18: Expedição | F18: =VLOOKUP('Fluxo CC 7369'!D18,Planilha1!B:C,2,0) -> 227
A19: 33756 | B19: 33756 | C19: -3908.37 | D19: Cursos E Treinamentos | E19: Administrativo | F19: =VLOOKUP('Fluxo CC 7369'!D19,Planilha1!B:C,2,0) -> 211
... A32: 33769 | B32: 33769 | C32: -439.47 | D32: Marketing E Publicidade | E32: CPC Online | F32: =VLOOKUP('Fluxo CC 7369'!D32,Planilha1!B:C,2,0) -> 245
A33: 33770 | B33: 33770 | C33: -15,38 | D33: Despesas Bancárias | E33: Financeiro | F33: =VLOOKUP('Fluxo CC 7369'!D33,Planilha1!B:C,2,0) -> 252

Sheet Planilha1
A1: Codigo | B1: Descrição | C1: Contas contábeis
A2: 0 | B2: Cod 0561 | Cod 1082 | Cod 1138 | Cod 1170 | Cod 1176 | Cod 1191 | Cod 1196 | Cod 1200 | Cod 1646 | Cod 8301 | C2: 62
A3: 2 | B3: VENDA DE LIVROS | C3: 132 a 134
A4: 3 | B4: AQUISIÇÃO DE LIVROS | C4: 28
A5: 4 | B5: VENDA DE EBOOK | C5: 134
A6: 10 | B6: 13º Salário | C6: 180 a 192
A7: 11 | B7: Despesas Editorial - Capa | C7: 752
A8: 12 | B8: Despesas Editorial - Conferência de Emendas | Despesas Editorial - Revisão de Prova | C8: 752
A9: 13 | B9: Despesas Editorial - Diagramação | C9: 185
A10: 14 | B10: Despesas Editorial - Edição | C10: 185
A11: 15 | B11: Despesas Editorial - Ilustração | C11: 752
A12: 16 | B12: Despesas Editorial - Preparação | C12: 752
A13: 17 | B13: Despesas Editorial - Produção Editorial | C13: 752
A14: 18 | B14: Despesas Editorial - Revisão de Prova | C14: 752
A15: 19 | B15: Despesas Editorial - Tradução | C15: 752
A16: 20 | B16: Materiais Para Revenda | C16: 80
A17: 21 | B17: Producao Material Proprio | C17: 80
A18: 21 | B18: Produção Material Próprio | C18: 80
... A75: 77 | B75: Impostos E Taxas | C75: 225
A76: 78 | B76: Estorno e Reembolso | C76: 231 LANÇAR NA NATUREZA DA DESPESA
A77: 79 | B77: Internet | C77: 233
A78: 80 | B78: Monitoramento Sede | C78: 67
A79: 81 | B79: Royalties | C79: 165
A80: 82 | B80: PIS 8301 | C80: 197
A81: 83 | B81: Terreno e Dependências - Sede | C81: 255
A82: 84 | B82: Sistemas e Softwares -Adm Marketing | C82: 244
A83: 85 | B83: Sistemas e Softwares Comerciais | C83: 710
A84: 86 | B84: Devolução de Venda | C84: 166
A85: 87 | B85: Exames médicos | C85: 193
A86: 88 | B86: Juros pagos/passivos | C86: 251
A87: 89 | B87: Lanches e Refeições Equipe | C87: 215
A88: 90 | B88: Lanches e Refeições Comercial | C88: 212
... A99: 101 | B99: Condomínio | C99: 237
A100: 102 | B100: DESPESAS OPERACIONAIS | C100: 4.3.1
A101: 103 | B101: DESPESAS ADMINISTRATIVAS | C101: 4.3.1.01
A102: 104 | B102: Materiais Impressos | C102: 224
A103: 105 | B103: Cod 0561 | C103: 67
A104: 106 | B104: TRANSFERENCIA ENTRE CONTAS | C104: 0
A105: 107 | B105: Despesas Bancárias | C105: 252
A106: 108 | B106: Rescisões | C106: 188 A 192
...
