Workbook

Sheet Planilha1
A1: Código | D1: Classificação | H1: Descrição | R1: Saldo Atual
H2: RECEITA COM VENDAS | R2: 495905.57
A3: 860 | D3: 3.1.1.03.0860 | I3: ATACADO | R3: 254042.11
A4: 861 | D4: 3.1.1.03.0861 | I4: ECOMMERCE | R4: 163266.31
A5: 865 | D5: 3.1.1.03.0865 | I5: LIVRARIA | R5: 78597.15
H6: MARKETPLACES | R6: 13298.19
A7: 863 | D7: 3.1.1.03.0863 | I7: AMAZON | R7: 11612.4
A8: 864 | D8: 3.1.1.03.0864 | I8: MERCADO LIVRE | R8: 1685.79
H9: TOTAL RECEITA BRUTA COM VENDAS | R9: 509203.76
H11: DEVOLUÇÃO E DESCONTO DE VENDAS | R11: -318.25
A12: 166 | D12: 3.6.1.01.0166 | I12: DEVOLUCAO DE VENDAS | R12: -296.45
A13: 168 | D13: 3.6.1.01.0168 | I13: DESCONTO SOBRE VENDAS | R13: -21.8
H14: RECEITA LÍQUIDA DE VENDAS | R14: 508885.51
H16: FRETE COBRADO DOS CLIENTES | R16: 35417.32
A17: 749 | D17: 3.1.1.04.0749 | I17: FRETES COBRADOS DOS CLIENTES | R17: 35417.32
H18: RECEITA OPERACIONAL TOTAL | R18: 544302.83
H20: CUSTO DOS PRODUTOS VENDIDOS (CPV/CMV) | R20: -229501.55
A21: 162 | D21: 3.7.1.01.0162 | I21: CUSTO DAS MERCADORIAS VENDIDAS | R21: -118537
A22: 165 | D22: 3.7.1.01.0165 | I22: DIREITOS AUTORAIS | R22: -39097.27
A23: 167 | D23: 3.7.1.01.0167 | I23: MATERIAIS APLICADOS NA VENDA DE PRODUTOS | R23: -2271.61
A24: 170 | D24: 3.7.1.01.0170 | I24: ROYALTIES EDITORIAIS E OUTROS | R24: -69595.67
H25: TOTAL CUSTO DOS PRODUTOS VENDIDOS | R25: -229501.55
H27: LUCRO BRUTO | R27: 314801.28
H29: DESPESAS VARIÁVEIS COMERCIAIS | R29: -45438.63
A30: 164 | D30: 3.7.1.01.0164 | I30: FRETES SOBRE MERCADORIAS | R30: -38368.67
A31: 206 | D31: 4.1.1.05.0206 | I31: COMISSOES POR VENDA | R31: -5380.07
A32: 212 | D32: 4.3.1.01.0212 | I32: DESPESAS REPRESENTACAO COMERCIAL | R32: -690.89
A33: 224 | D33: 4.3.1.01.0224 | I33: EMBALAGENS E MATERIAS GRAFICOS | R33: -999
H34: TAXA DE CARTAO / GATEWAY | R34: -7467.97
A35: 250 | D35: 4.3.1.03.0250 | I35: DESPESAS PAGAR ME | R35: -14.41
A36: 253 | D36: 4.3.1.03.0253 | I36: DESPESAS MERCADO PAGO.COM | R36: -127.84
A37: 651 | D37: 4.3.1.03.0651 | I37: DESPESAS AMAZON | R37: -192.64
A38: 653 | D38: 4.3.1.03.0653 | I38: DESPESAS STONE | R38: -39.71
A39: 654 | D39: 4.3.1.03.0654 | I39: DESPESAS VINDI | R39: -7093.37
H40: TOTAL DESPESAS VARIÁVEIS COMERCIAIS | R40: -52906.6
H42: MARGEM DE CONTRIBUIÇÃO | R42: 261894.68
H44: DESPESAS FIXAS OPERACIONAIS | R44: -73305.91
H46: DESPESA FIXA COMERCIAL | R46: -73305.91
H48: SALARIO FIXO DOS VENDEDORES | R48: -3214.9
A49: 182 | D49: 4.1.1.01.0182 | I49: COMERCIAL - PJ | R49: -3214.9
...

Sheet Planilha2
A1: Código | D1: Classificação | H1: Descrição | R1: Saldo Atual
H2: RECEITA COM VENDAS | R2: 418702.3
A3: 860 | D3: 3.1.1.03.0860 | I3: ATACADO | R3: 164622.6
A4: 861 | D4: 3.1.1.03.0861 | I4: ECOMMERCE | R4: 128055.93
A5: 862 | D5: 3.1.1.03.0862 | I5: EVENTO | R5: 47047.21
A6: 865 | D6: 3.1.1.03.0865 | I6: LIVRARIA | R6: 78976.56
H7: MARKETPLACES | R7: 4630.01
A8: 863 | D8: 3.1.1.03.0863 | I8: AMAZON | R8: 1393.5
A9: 864 | D9: 3.1.1.03.0864 | I9: MERCADO LIVRE | R9: 3236.51
H10: TOTAL RECEITA BRUTA COM VENDAS | R10: 423332.31
H12: DEVOLUÇÃO E DESCONTO DE VENDAS | R12: -743.82
A13: 166 | D13: 3.6.1.01.0166 | I13: DEVOLUCAO DE VENDAS | R13: -743.82
H14: RECEITA LÍQUIDA DE VENDAS | R14: 422588.49
H16: FRETE COBRADO DOS CLIENTES | R16: 25291.83
A17: 749 | D17: 3.1.1.04.0749 | I17: FRETES COBRADOS DOS CLIENTES | R17: 25291.83
H18: RECEITA OPERACIONAL TOTAL | R18: 447880.32
H20: CUSTO DOS PRODUTOS VENDIDOS (CPV/CMV) | R20: -205378.48
A21: 162 | D21: 3.7.1.01.0162 | I21: CUSTO DAS MERCADORIAS VENDIDAS | R21: -142495.37
A22: 165 | D22: 3.7.1.01.0165 | I22: DIREITOS AUTORAIS | R22: -22144.59
A23: 167 | D23: 3.7.1.01.0167 | I23: MATERIAIS APLICADOS NA VENDA DE PRODUTOS | R23: -1716.78
A24: 170 | D24: 3.7.1.01.0170 | I24: ROYALTIES EDITORIAIS E OUTROS | R24: -39021.74
H25: TOTAL CUSTO DOS PRODUTOS VENDIDOS | R25: -205378.48
H27: LUCRO BRUTO | R27: 242501.84
H29: DESPESAS VARIÁVEIS COMERCIAIS | R29: -37315.23
A30: 164 | D30: 3.7.1.01.0164 | I30: FRETES SOBRE MERCADORIAS | R30: -32396.03
A31: 206 | D31: 4.1.1.05.0206 | I31: COMISSOES POR VENDA | R31: -4301.18
A32: 212 | D32: 4.3.1.01.0212 | I32: DESPESAS REPRESENTACAO COMERCIAL | R32: -165.05
A33: 224 | D33: 4.3.1.01.0224 | I33: EMBALAGENS E MATERIAS GRAFICOS | R33: -452.97
H34: TAXA DE CARTAO / GATEWAY | R34: -6388.04
A35: 250 | D35: 4.3.1.03.0250 | I35: DESPESAS PAGAR ME | R35: -22.99
A36: 253 | D36: 4.3.1.03.0253 | I36: DESPESAS MERCADO PAGO.COM | R36: -106.44
A37: 651 | D37: 4.3.1.03.0651 | I37: DESPESAS AMAZON | R37: -85.23
A38: 653 | D38: 4.3.1.03.0653 | I38: DESPESAS STONE | R38: -70.31
A39: 654 | D39: 4.3.1.03.0654 | I39: DESPESAS VINDI | R39: -6103.07
H40: TOTAL DESPESAS VARIÁVEIS COMERCIAIS | R40: -43703.27
H42: MARGEM DE CONTRIBUIÇÃO | R42: 198798.57
H44: DESPESAS FIXAS OPERACIONAIS | R44: -90837.05
H46: DESPESA FIXA COMERCIAL | R46: -90837.05
H48: SALARIO FIXO DOS VENDEDORES | R48: -3214.9
A49: 182 | D49: 4.1.1.01.0182 | I49: COMERCIAL - PJ | R49: -3214.9
...

Sheet Planilha3
A1: Código | D1: Classificação | H1: Descrição | R1: Saldo Atual
H2: RECEITA COM VENDAS | R2: 467954.66
A3: 860 | D3: 3.1.1.03.0860 | I3: ATACADO | R3: 193567.41
A4: 861 | D4: 3.1.1.03.0861 | I4: ECOMMERCE | R4: 164134.17
A5: 862 | D5: 3.1.1.03.0862 | I5: EVENTO | R5: 20118.81
A6: 865 | D6: 3.1.1.03.0865 | I6: LIVRARIA | R6: 90134.27
H7: MARKETPLACES | R7: 28379.02
A8: 863 | D8: 3.1.1.03.0863 | I8: AMAZON | R8: 22701.73
A9: 864 | D9: 3.1.1.03.0864 | I9: MERCADO LIVRE | R9: 5677.29
H10: TOTAL RECEITA BRUTA COM VENDAS | R10: 496333.68
H12: DEVOLUÇÃO E DESCONTO DE VENDAS | R12: -109.63
A13: 166 | D13: 3.6.1.01.0166 | I13: DEVOLUCAO DE VENDAS | R13: -109.63
H14: RECEITA LÍQUIDA DE VENDAS | R14: 496224.05
H16: FRETE COBRADO DOS CLIENTES | R16: 29999.19
A17: 749 | D17: 3.1.1.04.0749 | I17: FRETES COBRADOS DOS CLIENTES | R17: 29999.19
H18: RECEITA OPERACIONAL TOTAL | R18: 526223.24
H20: CUSTO DOS PRODUTOS VENDIDOS (CPV/CMV) | R20: -262495.89
A21: 162 | D21: 3.7.1.01.0162 | I21: CUSTO DAS MERCADORIAS VENDIDAS | R21: -202408.68
A22: 165 | D22: 3.7.1.01.0165 | I22: DIREITOS AUTORAIS | R22: -21519.93
A23: 167 | D23: 3.7.1.01.0167 | I23: MATERIAIS APLICADOS NA VENDA DE PRODUTOS | R23: -4910.46
A24: 170 | D24: 3.7.1.01.0170 | I24: ROYALTIES EDITORIAIS E OUTROS | R24: -33656.82
H25: TOTAL CUSTO DOS PRODUTOS VENDIDOS | R25: -262495.89
H27: LUCRO BRUTO | R27: 263727.35
H29: DESPESAS VARIÁVEIS COMERCIAIS | R29: -38241.74
A30: 164 | D30: 3.7.1.01.0164 | I30: FRETES SOBRE MERCADORIAS | R30: -30266.43
A31: 206 | D31: 4.1.1.05.0206 | I31: COMISSOES POR VENDA | R31: -4108.25
A32: 207 | D32: 4.1.1.05.0207 | I32: BONUS POR RESULTADO | R32: -3000
A33: 224 | D33: 4.3.1.01.0224 | I33: EMBALAGENS E MATERIAS GRAFICOS | R33: -867.06
H34: TAXA DE CARTAO / GATEWAY | R34: -11904.13
A35: 250 | D35: 4.3.1.03.0250 | I35: DESPESAS PAGAR ME | R35: -36.25
A36: 253 | D36: 4.3.1.03.0253 | I36: DESPESAS MERCADO PAGO.COM | R36: -120.19
A37: 651 | D37: 4.3.1.03.0651 | I37: DESPESAS AMAZON | R37: -3587.81
A38: 653 | D38: 4.3.1.03.0653 | I38: DESPESAS STONE | R38: -49.67
A39: 654 | D39: 4.3.1.03.0654 | I39: DESPESAS VINDI | R39: -8110.21
H40: TOTAL DESPESAS VARIÁVEIS COMERCIAIS | R40: -50145.87
H42: MARGEM DE CONTRIBUIÇÃO | R42: 213581.48
H44: DESPESAS FIXAS OPERACIONAIS | R44: -82984.22
H46: DESPESA FIXA COMERCIAL | R46: -82984.22
H48: SALARIO FIXO DOS VENDEDORES | R48: -3214.9
A49: 182 | D49: 4.1.1.01.0182 | I49: COMERCIAL - PJ | R49: -3214.9
...

Sheet Planilha4
A1: Código | D1: Classificação | H1: Descrição | R1: Saldo Atual
H2: RECEITA COM VENDAS | R2: 388073.88
A3: 860 | D3: 3.1.1.03.0860 | I3: ATACADO | R3: 132575.25
A4: 861 | D4: 3.1.1.03.0861 | I4: ECOMMERCE | R4: 161518.87
A5: 862 | D5: 3.1.1.03.0862 | I5: EVENTO | R5: 1613.05
A6: 865 | D6: 3.1.1.03.0865 | I6: LIVRARIA | R6: 92366.71
H7: MARKETPLACES | R7: 22410.2
A8: 863 | D8: 3.1.1.03.0863 | I8: AMAZON | R8: 19863
A9: 864 | D9: 3.1.1.03.0864 | I9: MERCADO LIVRE | R9: 2547.2
H10: TOTAL RECEITA BRUTA COM VENDAS | R10: 410484.08
H12: DEVOLUÇÃO E DESCONTO DE VENDAS | R12: -967.46
A13: 166 | D13: 3.6.1.01.0166 | I13: DEVOLUCAO DE VENDAS | R13: -967.46
H14: RECEITA LÍQUIDA DE VENDAS | R14: 409516.62
H16: FRETE COBRADO DOS CLIENTES | R16: 29685.64
A17: 749 | D17: 3.1.1.04.0749 | I17: FRETES COBRADOS DOS CLIENTES | R17: 29685.64
H18: RECEITA OPERACIONAL TOTAL | R18: 439202.26
H20: CUSTO DOS PRODUTOS VENDIDOS (CPV/CMV) | R20: -216442.65
A21: 162 | D21: 3.7.1.01.0162 | I21: CUSTO DAS MERCADORIAS VENDIDAS | R21: -171775.47
A22: 165 | D22: 3.7.1.01.0165 | I22: DIREITOS AUTORAIS | R22: -15091.45
A23: 167 | D23: 3.7.1.01.0167 | I23: MATERIAIS APLICADOS NA VENDA DE PRODUTOS | R23: -2405.33
A24: 170 | D24: 3.7.1.01.0170 | I24: ROYALTIES EDITORIAIS E OUTROS | R24: -27170.4
H25: TOTAL CUSTO DOS PRODUTOS VENDIDOS | R25: -216442.65
H27: RECEITAS FINANCEIRAS | R27: 10.49
A28: 135 | D28: 3.2.1.01.0135 | I28: FUNDOS DIVERSOS | R28: 10.49
H29: LUCRO BRUTO | R29: 222770.1
H31: DESPESAS VARIÁVEIS COMERCIAIS | R31: -36743.93
A32: 164 | D32: 3.7.1.01.0164 | I32: FRETES SOBRE MERCADORIAS | R32: -31117.68
A33: 206 | D33: 4.1.1.05.0206 | I33: COMISSOES POR VENDA | R33: -2657.31
A34: 212 | D34: 4.3.1.01.0212 | I34: DESPESAS REPRESENTACAO COMERCIAL | R34: -969
A35: 224 | D35: 4.3.1.01.0224 | I35: EMBALAGENS E MATERIAS GRAFICOS | R35: -1999.94
H36: TAXA DE CARTAO / GATEWAY | R36: -12710.26
A37: 250 | D37: 4.3.1.03.0250 | I37: DESPESAS PAGAR ME | R37: -62.91
A38: 253 | D38: 4.3.1.03.0253 | I38: DESPESAS MERCADO PAGO.COM | R38: -719.07
A39: 651 | D39: 4.3.1.03.0651 | I39: DESPESAS AMAZON | R39: -1874.88
A40: 653 | D40: 4.3.1.03.0653 | I40: DESPESAS STONE | R40: -70.3
A41: 654 | D41: 4.3.1.03.0654 | I41: DESPESAS VINDI | R41: -9983.1
H42: TOTAL DESPESAS VARIÁVEIS COMERCIAIS | R42: -49454.19
H44: MARGEM DE CONTRIBUIÇÃO | R44: 173315.91
H46: DESPESAS FIXAS OPERACIONAIS | R46: -97464.56
H48: DESPESA FIXA COMERCIAL | R48: -97464.56
...

Sheet Planilha5
A1: Código | D1: Classificação | H1: Descrição | R1: Saldo Atual
H2: RECEITA COM VENDAS | R2: 503039.55
A3: 860 | D3: 3.1.1.03.0860 | I3: ATACADO | R3: 219556.41
A4: 861 | D4: 3.1.1.03.0861 | I4: ECOMMERCE | R4: 167517.93
A5: 862 | D5: 3.1.1.03.0862 | I5: EVENTO | R5: 2953.61
A6: 865 | D6: 3.1.1.03.0865 | I6: LIVRARIA | R6: 113011.6
H7: MARKETPLACES | R7: 14548.79
A8: 863 | D8: 3.1.1.03.0863 | I8: AMAZON | R8: 11019.65
A9: 864 | D9: 3.1.1.03.0864 | I9: MERCADO LIVRE | R9: 3529.14
H10: TOTAL RECEITA BRUTA COM VENDAS | R10: 517588.34
H12: DEVOLUÇÃO E DESCONTO DE VENDAS | R12: -569.8
A13: 166 | D13: 3.6.1.01.0166 | I13: DEVOLUCAO DE VENDAS | R13: -569.8
H14: RECEITA LÍQUIDA DE VENDAS | R14: 517018.54
H16: FRETE COBRADO DOS CLIENTES | R16: 34698.87
A17: 749 | D17: 3.1.1.04.0749 | I17: FRETES COBRADOS DOS CLIENTES | R17: 34698.87
H18: RECEITA OPERACIONAL TOTAL | R18: 551717.41
H20: CUSTO DOS PRODUTOS VENDIDOS (CPV/CMV) | R20: -316722.03
A21: 162 | D21: 3.7.1.01.0162 | I21: CUSTO DAS MERCADORIAS VENDIDAS | R21: -216281.18
A22: 165 | D22: 3.7.1.01.0165 | I22: DIREITOS AUTORAIS | R22: -20504.68
A23: 167 | D23: 3.7.1.01.0167 | I23: MATERIAIS APLICADOS NA VENDA DE PRODUTOS | R23: -281.7
A24: 170 | D24: 3.7.1.01.0170 | I24: ROYALTIES EDITORIAIS E OUTROS | R24: -79654.47
H25: TOTAL CUSTO DOS PRODUTOS VENDIDOS | R25: -316722.03
H27: LUCRO BRUTO | R27: 234995.38
H29: DESPESAS VARIÁVEIS COMERCIAIS | R29: -46248.31
A30: 164 | D30: 3.7.1.01.0164 | I30: FRETES SOBRE MERCADORIAS | R30: -39597.87
A31: 206 | D31: 4.1.1.05.0206 | I31: COMISSOES POR VENDA | R31: -3650.44
A32: 207 | D32: 4.1.1.05.0207 | I32: BONUS POR RESULTADO | R32: -3000
H33: TAXA DE CARTAO / GATEWAY | R33: -10745.85
A34: 250 | D34: 4.3.1.03.0250 | I34: DESPESAS PAGAR ME | R34: -114.26
A35: 253 | D35: 4.3.1.03.0253 | I35: DESPESAS MERCADO PAGO.COM | R35: -1200.21
A36: 651 | D36: 4.3.1.03.0651 | I36: DESPESAS AMAZON | R36: -104.59
A37: 653 | D37: 4.3.1.03.0653 | I37: DESPESAS STONE | R37: -61.8
A38: 654 | D38: 4.3.1.03.0654 | I38: DESPESAS VINDI | R38: -9264.99
H39: TOTAL DESPESAS VARIÁVEIS COMERCIAIS | R39: -56994.16
H41: MARGEM DE CONTRIBUIÇÃO | R41: 178001.22
H43: DESPESAS FIXAS OPERACIONAIS | R43: -83740.92
H45: DESPESA FIXA COMERCIAL | R45: -83740.92
H47: SALARIO FIXO DOS VENDEDORES | R47: -3214.9
A48: 182 | D48: 4.1.1.01.0182 | I48: COMERCIAL - PJ | R48: -3214.9
H49: EQUIPE DE MARKETING | R49: -25711.19
...

Sheet Planilha6
A1: Código | D1: Classificação | H1: Descrição | R1: Saldo Atual
H2: RECEITA COM VENDAS | R2: 347333.52
A3: 860 | D3: 3.1.1.03.0860 | I3: ATACADO | R3: 60852.57
A4: 861 | D4: 3.1.1.03.0861 | I4: ECOMMERCE | R4: 173821.57
A5: 862 | D5: 3.1.1.03.0862 | I5: EVENTO | R5: 4466.5
A6: 865 | D6: 3.1.1.03.0865 | I6: LIVRARIA | R6: 108192.88
H7: MARKETPLACES | R7: 32617.49
A8: 863 | D8: 3.1.1.03.0863 | I8: AMAZON | R8: 11271.66
A9: 864 | D9: 3.1.1.03.0864 | I9: MERCADO LIVRE | R9: 18965.25
A10: 866 | D10: 3.1.1.03.0866 | I10: FULL ML | R10: 2281.66
A11: 867 | D11: 3.1.1.03.0867 | I11: TIKTOK | R11: 98.92
H12: TOTAL RECEITA BRUTA COM VENDAS | R12: 379951.01
H14: DEVOLUÇÃO E DESCONTO DE VENDAS | R14: -1607.93
A15: 166 | D15: 3.6.1.01.0166 | I15: DEVOLUCAO DE VENDAS | R15: -1607.93
H16: RECEITA LÍQUIDA DE VENDAS | R16: 378343.08
H18: FRETE COBRADO DOS CLIENTES | R18: 26661.5
A19: 749 | D19: 3.1.1.04.0749 | I19: FRETES COBRADOS DOS CLIENTES | R19: 26661.5
H20: RECEITA OPERACIONAL TOTAL | R20: 405004.58
H22: CUSTO DOS PRODUTOS VENDIDOS (CPV/CMV) | R22: -128709.05
A23: 162 | D23: 3.7.1.01.0162 | I23: CUSTO DAS MERCADORIAS VENDIDAS | R23: -126681.55
A24: 165 | D24: 3.7.1.01.0165 | I24: DIREITOS AUTORAIS | R24: -1895.08
A25: 170 | D25: 3.7.1.01.0170 | I25: ROYALTIES EDITORIAIS E OUTROS | R25: -132.42
H26: TOTAL CUSTO DOS PRODUTOS VENDIDOS | R26: -128709.05
H28: RECEITAS FINANCEIRAS | R28: 4.16
A29: 135 | D29: 3.2.1.01.0135 | I29: FUNDOS DIVERSOS | R29: 4.16
H30: OUTRAS RECEITAS | R30: 8.9
A31: 159 | D31: 3.3.1.01.0159 | I31: OUTRAS RECEITAS | R31: 8.9
H32: LUCRO BRUTO | R32: 276308.59
H34: DESPESAS VARIÁVEIS COMERCIAIS | R34: -33737.16
A35: 164 | D35: 3.7.1.01.0164 | I35: FRETES SOBRE MERCADORIAS | R35: -27086.72
A36: 206 | D36: 4.1.1.05.0206 | I36: COMISSOES POR VENDA | R36: -3650.44
A37: 207 | D37: 4.1.1.05.0207 | I37: BONUS POR RESULTADO | R37: -3000
H38: TAXA DE CARTAO / GATEWAY | R38: -17952.99
A39: 250 | D39: 4.3.1.03.0250 | I39: DESPESAS PAGAR ME | R39: -23.94
A40: 253 | D40: 4.3.1.03.0253 | I40: DESPESAS MERCADO PAGO.COM | R40: -9031.48
A41: 651 | D41: 4.3.1.03.0651 | I41: DESPESAS AMAZON | R41: -822.32
A42: 653 | D42: 4.3.1.03.0653 | I42: DESPESAS STONE | R42: -53.09
A43: 654 | D43: 4.3.1.03.0654 | I43: DESPESAS VINDI | R43: -8022.16
H44: TOTAL DESPESAS VARIÁVEIS COMERCIAIS | R44: -51690.15
H46: MARGEM DE CONTRIBUIÇÃO | R46: 224618.44
...

Sheet Planilha7
A1: Código | D1: Classificação | H1: Descrição | R1: Saldo Atual
H2: RECEITA COM VENDAS | R2: 316622.52
A3: 860 | D3: 3.1.1.03.0860 | I3: ATACADO | R3: 60934.28
A4: 861 | D4: 3.1.1.03.0861 | I4: ECOMMERCE | R4: 158614.03
A5: 862 | D5: 3.1.1.03.0862 | I5: EVENTO | R5: 193.79
A6: 865 | D6: 3.1.1.03.0865 | I6: LIVRARIA | R6: 96573.67
A7: 868 | D7: 3.1.1.03.0868 | I7: SHOWROOM | R7: 306.75
H8: MARKETPLACES | R8: 52521.49
A9: 863 | D9: 3.1.1.03.0863 | I9: AMAZON | R9: 5295.83
A10: 864 | D10: 3.1.1.03.0864 | I10: MERCADO LIVRE | R10: 26286.41
A11: 866 | D11: 3.1.1.03.0866 | I11: FULL ML | R11: 20939.25
H12: TOTAL RECEITA BRUTA COM VENDAS | R12: 369144.01
H14: DEVOLUÇÃO E DESCONTO DE VENDAS | R14: -3996.41
A15: 166 | D15: 3.6.1.01.0166 | I15: DEVOLUCAO DE VENDAS | R15: -3996.41
H16: RECEITA LÍQUIDA DE VENDAS | R16: 365147.6
H18: FRETE COBRADO DOS CLIENTES | R18: 25319.27
A19: 749 | D19: 3.1.1.04.0749 | I19: FRETES COBRADOS DOS CLIENTES | R19: 25319.27
H20: RECEITA OPERACIONAL TOTAL | R20: 390466.87
H22: CUSTO DOS PRODUTOS VENDIDOS (CPV/CMV) | R22: -119343.78
A23: 162 | D23: 3.7.1.01.0162 | I23: CUSTO DAS MERCADORIAS VENDIDAS | R23: -116012.28
A24: 165 | D24: 3.7.1.01.0165 | I24: DIREITOS AUTORAIS | R24: -2867.37
A25: 170 | D25: 3.7.1.01.0170 | I25: ROYALTIES EDITORIAIS E OUTROS | R25: -464.13
H26: TOTAL CUSTO DOS PRODUTOS VENDIDOS | R26: -119343.78
H28: RECEITAS FINANCEIRAS | R28: 0.76
A29: 135 | D29: 3.2.1.01.0135 | I29: FUNDOS DIVERSOS | R29: 0.76
H30: OUTRAS RECEITAS | R30: 78.94
A31: 159 | D31: 3.3.1.01.0159 | I31: OUTRAS RECEITAS | R31: 78.94
H32: LUCRO BRUTO | R32: 271202.79
H34: DESPESAS VARIÁVEIS COMERCIAIS | R34: -29155.49
A35: 164 | D35: 3.7.1.01.0164 | I35: FRETES SOBRE MERCADORIAS | R35: -25733.24
A36: 206 | D36: 4.1.1.05.0206 | I36: COMISSOES POR VENDA | R36: -104.79
A37: 207 | D37: 4.1.1.05.0207 | I37: BONUS POR RESULTADO | R37: -750
A38: 224 | D38: 4.3.1.01.0224 | I38: EMBALAGENS E MATERIAS GRAFICOS | R38: -2567.46
H39: TAXA DE CARTAO / GATEWAY | R39: -26613.38
A40: 250 | D40: 4.3.1.03.0250 | I40: DESPESAS PAGAR ME | R40: -8.06
A41: 253 | D41: 4.3.1.03.0253 | I41: DESPESAS MERCADO PAGO.COM | R41: -19449.37
A42: 651 | D42: 4.3.1.03.0651 | I42: DESPESAS AMAZON | R42: -359.72
A43: 653 | D43: 4.3.1.03.0653 | I43: DESPESAS STONE | R43: -60.02
A44: 654 | D44: 4.3.1.03.0654 | I44: DESPESAS VINDI | R44: -6736.21
H45: TOTAL DESPESAS VARIÁVEIS COMERCIAIS | R45: -55768.87
...

Sheet Planilha8
A1: Código | D1: Classificação | H1: Descrição | R1: Saldo Atual
H2: RECEITA COM VENDAS | R2: 393480.25
A3: 860 | D3: 3.1.1.03.0860 | I3: ATACADO | R3: 67772.31
A4: 861 | D4: 3.1.1.03.0861 | I4: ECOMMERCE | R4: 183185.27
A5: 862 | D5: 3.1.1.03.0862 | I5: EVENTO | R5: 5920.9
A6: 865 | D6: 3.1.1.03.0865 | I6: LIVRARIA | R6: 132362.67
A7: 868 | D7: 3.1.1.03.0868 | I7: SHOWROOM | R7: 4239.1
H8: MARKETPLACES | R8: 102348.89
A9: 863 | D9: 3.1.1.03.0863 | I9: AMAZON | R9: 12708.58
A10: 864 | D10: 3.1.1.03.0864 | I10: MERCADO LIVRE | R10: 56458.35
A11: 866 | D11: 3.1.1.03.0866 | I11: FULL ML | R11: 27487.96
A12: 869 | D12: 3.1.1.03.0869 | I12: AMAZON FULL | R12: 5694
H13: TOTAL RECEITA BRUTA COM VENDAS | R13: 495829.14
H15: DEVOLUÇÃO E DESCONTO DE VENDAS | R15: -4964.76
A16: 166 | D16: 3.6.1.01.0166 | I16: DEVOLUCAO DE VENDAS | R16: -4964.76
H17: RECEITA LÍQUIDA DE VENDAS | R17: 490864.38
H19: FRETE COBRADO DOS CLIENTES | R19: 27185.91
A20: 749 | D20: 3.1.1.04.0749 | I20: FRETES COBRADOS DOS CLIENTES | R20: 27185.91
H21: RECEITA OPERACIONAL TOTAL | R21: 518050.29
H23: CUSTO DOS PRODUTOS VENDIDOS (CPV/CMV) | R23: -197655.91
A24: 162 | D24: 3.7.1.01.0162 | I24: CUSTO DAS MERCADORIAS VENDIDAS | R24: -187451.29
A25: 165 | D25: 3.7.1.01.0165 | I25: DIREITOS AUTORAIS | R25: -8035.08
A26: 167 | D26: 3.7.1.01.0167 | I26: MATERIAIS APLICADOS NA VENDA DE PRODUTOS | R26: -2169.54
H27: TOTAL CUSTO DOS PRODUTOS VENDIDOS | R27: -197655.91
H29: RECEITAS FINANCEIRAS | R29: 3.2
A30: 135 | D30: 3.2.1.01.0135 | I30: FUNDOS DIVERSOS | R30: 3.2
H31: OUTRAS RECEITAS | R31: 352.76
A32: 159 | D32: 3.3.1.01.0159 | I32: OUTRAS RECEITAS | R32: 352.76
H33: LUCRO BRUTO | R33: 320750.34
H35: DESPESAS VARIÁVEIS COMERCIAIS | R35: -23752.08
A36: 164 | D36: 3.7.1.01.0164 | I36: FRETES SOBRE MERCADORIAS | R36: -22182.95
A37: 206 | D37: 4.1.1.05.0206 | I37: COMISSOES POR VENDA | R37: -219.13
A38: 207 | D38: 4.1.1.05.0207 | I38: BONUS POR RESULTADO | R38: -1350
H39: TAXA DE CARTAO / GATEWAY | R39: -32006.59
A40: 250 | D40: 4.3.1.03.0250 | I40: DESPESAS PAGAR ME | R40: -18.34
A41: 253 | D41: 4.3.1.03.0253 | I41: DESPESAS MERCADO PAGO.COM | R41: -24004
A42: 651 | D42: 4.3.1.03.0651 | I42: DESPESAS AMAZON | R42: -331.66
A43: 653 | D43: 4.3.1.03.0653 | I43: DESPESAS STONE | R43: -86.19
A44: 654 | D44: 4.3.1.03.0654 | I44: DESPESAS VINDI | R44: -7566.4
H45: TOTAL DESPESAS VARIÁVEIS COMERCIAIS | R45: -55758.67
...

Sheet Planilha9
A1: Código | D1: Classificação | H1: Descrição | R1: Saldo Atual
H2: RECEITA COM VENDAS | R2: 365887.99
A3: 860 | D3: 3.1.1.03.0860 | I3: ATACADO | R3: 119355.57
A4: 861 | D4: 3.1.1.03.0861 | I4: ECOMMERCE | R4: 128905.32
A5: 862 | D5: 3.1.1.03.0862 | I5: EVENTO | R5: 2022.62
A6: 865 | D6: 3.1.1.03.0865 | I6: LIVRARIA | R6: 108371.46
A7: 868 | D7: 3.1.1.03.0868 | I7: SHOWROOM | R7: 7233.02
H8: MARKETPLACES | R8: 76825.93
A9: 863 | D9: 3.1.1.03.0863 | I9: AMAZON | R9: 14195.45
A10: 864 | D10: 3.1.1.03.0864 | I10: MERCADO LIVRE | R10: 36501
A11: 866 | D11: 3.1.1.03.0866 | I11: FULL ML | R11: 22983.78
A12: 869 | D12: 3.1.1.03.0869 | I12: AMAZON FULL | R12: 3145.7
H13: TOTAL RECEITA BRUTA COM VENDAS | R13: 442713.92
H15: DEVOLUÇÃO E DESCONTO DE VENDAS | R15: -5299.1
A16: 166 | D16: 3.6.1.01.0166 | I16: DEVOLUCAO DE VENDAS | R16: -5299.1
H17: RECEITA LÍQUIDA DE VENDAS | R17: 437414.82
H19: FRETE COBRADO DOS CLIENTES | R19: 20968.57
A20: 749 | D20: 3.1.1.04.0749 | I20: FRETES COBRADOS DOS CLIENTES | R20: 20968.57
H21: RECEITA OPERACIONAL TOTAL | R21: 458383.39
H23: CUSTO DOS PRODUTOS VENDIDOS (CPV/CMV) | R23: -116814.82
A24: 162 | D24: 3.7.1.01.0162 | I24: CUSTO DAS MERCADORIAS VENDIDAS | R24: -103605.83
A25: 165 | D25: 3.7.1.01.0165 | I25: DIREITOS AUTORAIS | R25: -13208.99
H26: TOTAL CUSTO DOS PRODUTOS VENDIDOS | R26: -116814.82
H28: RECEITAS FINANCEIRAS | R28: 3.21
A29: 135 | D29: 3.2.1.01.0135 | I29: FUNDOS DIVERSOS | R29: 3.21
H30: OUTRAS RECEITAS | R30: 3834.2
A31: 159 | D31: 3.3.1.01.0159 | I31: OUTRAS RECEITAS | R31: 3834.2
H32: LUCRO BRUTO | R32: 345405.98
H34: DESPESAS VARIÁVEIS COMERCIAIS | R34: -32588.96
A35: 164 | D35: 3.7.1.01.0164 | I35: FRETES SOBRE MERCADORIAS | R35: -20189.25
A36: 206 | D36: 4.1.1.05.0206 | I36: COMISSOES POR VENDA | R36: -569.13
A37: 207 | D37: 4.1.1.05.0207 | I37: BONUS POR RESULTADO | R37: -7509.27
A38: 224 | D38: 4.3.1.01.0224 | I38: EMBALAGENS E MATERIAS GRAFICOS | R38: -4321.31
H39: TAXA DE CARTAO / GATEWAY | R39: -23346.11
A40: 250 | D40: 4.3.1.03.0250 | I40: DESPESAS PAGAR ME | R40: -18.54
A41: 253 | D41: 4.3.1.03.0253 | I41: DESPESAS MERCADO PAGO.COM | R41: -14867.44
A42: 651 | D42: 4.3.1.03.0651 | I42: DESPESAS AMAZON | R42: -331.66
A43: 653 | D43: 4.3.1.03.0653 | I43: DESPESAS STONE | R43: -59.23
A44: 654 | D44: 4.3.1.03.0654 | I44: DESPESAS VINDI | R44: -8069.24
H45: TOTAL DESPESAS VARIÁVEIS COMERCIAIS | R45: -55935.07
...

Sheet Planilha10
A1: Código | D1: Classificação | H1: Descrição | R1: Saldo Atual
H2: RECEITA COM VENDAS | R2: 581307.37
A3: 860 | D3: 3.1.1.03.0860 | I3: ATACADO | R3: 103628.97
A4: 861 | D4: 3.1.1.03.0861 | I4: ECOMMERCE | R4: 362077.95
A5: 865 | D5: 3.1.1.03.0865 | I5: LIVRARIA | R5: 114754.37
A6: 868 | D6: 3.1.1.03.0868 | I6: SHOWROOM | R6: 846.08
H7: MARKETPLACES | R7: 66278.9
A8: 863 | D8: 3.1.1.03.0863 | I8: AMAZON | R8: 23873.87
A9: 864 | D9: 3.1.1.03.0864 | I9: MERCADO LIVRE | R9: 17237.34
A10: 866 | D10: 3.1.1.03.0866 | I10: FULL ML | R10: 22021.99
A11: 869 | D11: 3.1.1.03.0869 | I11: AMAZON FULL | R11: 3145.7
H12: TOTAL RECEITA BRUTA COM VENDAS | R12: 647586.27
H14: DEVOLUÇÃO E DESCONTO DE VENDAS | R14: -1467.16
A15: 166 | D15: 3.6.1.01.0166 | I15: DEVOLUCAO DE VENDAS | R15: -1467.16
H16: RECEITA LÍQUIDA DE VENDAS | R16: 646119.11
H18: FRETE COBRADO DOS CLIENTES | R18: 34011.27
A19: 749 | D19: 3.1.1.04.0749 | I19: FRETES COBRADOS DOS CLIENTES | R19: 34011.27
H20: RECEITA OPERACIONAL TOTAL | R20: 680130.38
H22: CUSTO DOS PRODUTOS VENDIDOS (CPV/CMV) | R22: -149255.1
A23: 162 | D23: 3.7.1.01.0162 | I23: CUSTO DAS MERCADORIAS VENDIDAS | R23: -137158.93
A24: 165 | D24: 3.7.1.01.0165 | I24: DIREITOS AUTORAIS | R24: -9114.17
A25: 167 | D25: 3.7.1.01.0167 | I25: MATERIAIS APLICADOS NA VENDA DE PRODUTOS | R25: -2982
H26: TOTAL CUSTO DOS PRODUTOS VENDIDOS | R26: -149255.1
H28: OUTRAS RECEITAS | R28: 1552.28
A29: 159 | D29: 3.3.1.01.0159 | I29: OUTRAS RECEITAS | R29: 1552.28
H30: LUCRO BRUTO | R30: 532427.56
H32: DESPESAS VARIÁVEIS COMERCIAIS | R32: -43020.04
A33: 164 | D33: 3.7.1.01.0164 | I33: FRETES SOBRE MERCADORIAS | R33: -29566.35
A34: 206 | D34: 4.1.1.05.0206 | I34: COMISSOES POR VENDA | R34: -2093.42
A35: 207 | D35: 4.1.1.05.0207 | I35: BONUS POR RESULTADO | R35: -7284.27
A36: 224 | D36: 4.3.1.01.0224 | I36: EMBALAGENS E MATERIAS GRAFICOS | R36: -4076
H37: TAXA DE CARTAO / GATEWAY | R37: -20628.88
A38: 250 | D38: 4.3.1.03.0250 | I38: DESPESAS PAGAR ME | R38: -9485.26
A39: 253 | D39: 4.3.1.03.0253 | I39: DESPESAS MERCADO PAGO.COM | R39: -10888.27
A40: 651 | D40: 4.3.1.03.0651 | I40: DESPESAS AMAZON | R40: -187.73
A41: 653 | D41: 4.3.1.03.0653 | I41: DESPESAS STONE | R41: -67.62
H42: TOTAL DESPESAS VARIÁVEIS COMERCIAIS | R42: -63648.92
H44: MARGEM DE CONTRIBUIÇÃO | R44: 468778.64
H46: DESPESAS FIXAS OPERACIONAIS | R46: -136596.67
H48: DESPESA FIXA COMERCIAL | R48: -136596.67
...

Sheet Planilha11
A1: Código | D1: Classificação | H1: Descrição | R1: Saldo Atual
H2: RECEITA COM VENDAS | R2: 721066.96
A3: 860 | D3: 3.1.1.03.0860 | I3: ATACADO | R3: 81748.93
A4: 861 | D4: 3.1.1.03.0861 | I4: ECOMMERCE | R4: 337371.61
A5: 862 | D5: 3.1.1.03.0862 | I5: EVENTO | R5: 139352.76
A6: 865 | D6: 3.1.1.03.0865 | I6: LIVRARIA | R6: 159575.85
A7: 868 | D7: 3.1.1.03.0868 | I7: SHOWROOM | R7: 3017.81
H8: MARKETPLACES | R8: 97895.65
A9: 863 | D9: 3.1.1.03.0863 | I9: AMAZON | R9: 43014.56
A10: 864 | D10: 3.1.1.03.0864 | I10: MERCADO LIVRE | R10: 34575.46
A11: 866 | D11: 3.1.1.03.0866 | I11: FULL ML | R11: 19076.53
A12: 869 | D12: 3.1.1.03.0869 | I12: AMAZON FULL | R12: 1229.1
H13: TOTAL RECEITA BRUTA COM VENDAS | R13: 818962.61
H15: DEVOLUÇÃO E DESCONTO DE VENDAS | R15: -2839.49
A16: 166 | D16: 3.6.1.01.0166 | I16: DEVOLUCAO DE VENDAS | R16: -2839.49
H17: RECEITA LÍQUIDA DE VENDAS | R17: 816123.12
H19: FRETE COBRADO DOS CLIENTES | R19: 41078.72
A20: 749 | D20: 3.1.1.04.0749 | I20: FRETES COBRADOS DOS CLIENTES | R20: 41078.72
H21: RECEITA OPERACIONAL TOTAL | R21: 857201.84
H23: CUSTO DOS PRODUTOS VENDIDOS (CPV/CMV) | R23: -295912.48
A24: 162 | D24: 3.7.1.01.0162 | I24: CUSTO DAS MERCADORIAS VENDIDAS | R24: -252632.58
A25: 165 | D25: 3.7.1.01.0165 | I25: DIREITOS AUTORAIS | R25: -43279.9
H26: TOTAL CUSTO DOS PRODUTOS VENDIDOS | R26: -295912.48
H28: RECEITAS FINANCEIRAS | R28: 1.69
A29: 135 | D29: 3.2.1.01.0135 | I29: FUNDOS DIVERSOS | R29: 1.69
H30: OUTRAS RECEITAS | R30: 260.45
A31: 159 | D31: 3.3.1.01.0159 | I31: OUTRAS RECEITAS | R31: 260.45
H32: LUCRO BRUTO | R32: 561551.5
H34: DESPESAS VARIÁVEIS COMERCIAIS | R34: -69590.53
A35: 164 | D35: 3.7.1.01.0164 | I35: FRETES SOBRE MERCADORIAS | R35: -42892.46
A36: 206 | D36: 4.1.1.05.0206 | I36: COMISSOES POR VENDA | R36: -2570.34
A37: 207 | D37: 4.1.1.05.0207 | I37: BONUS POR RESULTADO | R37: -16501.75
A38: 224 | D38: 4.3.1.01.0224 | I38: EMBALAGENS E MATERIAS GRAFICOS | R38: -7625.98
H39: TAXA DE CARTAO / GATEWAY | R39: -37959.16
A40: 250 | D40: 4.3.1.03.0250 | I40: DESPESAS PAGAR ME | R40: -13576.69
A41: 253 | D41: 4.3.1.03.0253 | I41: DESPESAS MERCADO PAGO.COM | R41: -22440.42
A42: 651 | D42: 4.3.1.03.0651 | I42: DESPESAS AMAZON | R42: -149.29
A43: 653 | D43: 4.3.1.03.0653 | I43: DESPESAS STONE | R43: -146.22
A44: 654 | D44: 4.3.1.03.0654 | I44: DESPESAS VINDI | R44: -1646.54
H45: TOTAL DESPESAS VARIÁVEIS COMERCIAIS | R45: -107549.69
...

Sheet Planilha12
A1: Código | D1: Classificação | H1: Descrição | R1: Saldo Atual
H2: RECEITA COM VENDAS | R2: 891397.91
A3: 860 | D3: 3.1.1.03.0860 | I3: ATACADO | R3: 302775.76
A4: 861 | D4: 3.1.1.03.0861 | I4: ECOMMERCE | R4: 451807.46
A5: 865 | D5: 3.1.1.03.0865 | I5: LIVRARIA | R5: 135979.09
A6: 868 | D6: 3.1.1.03.0868 | I6: SHOWROOM | R6: 835.6
H7: MARKETPLACES | R7: 217313.13
A8: 863 | D8: 3.1.1.03.0863 | I8: AMAZON | R8: 62324.86
A9: 864 | D9: 3.1.1.03.0864 | I9: MERCADO LIVRE | R9: 143877.78
A10: 866 | D10: 3.1.1.03.0866 | I10: FULL ML | R10: 9019.49
A11: 869 | D11: 3.1.1.03.0869 | I11: AMAZON FULL | R11: 2091
H12: TOTAL RECEITA BRUTA COM VENDAS | R12: 1108711
H14: DEVOLUÇÃO E DESCONTO DE VENDAS | R14: -4693.04
A15: 166 | D15: 3.6.1.01.0166 | I15: DEVOLUCAO DE VENDAS | R15: -4693.04
H16: RECEITA LÍQUIDA DE VENDAS | R16: 1104018
H18: FRETE COBRADO DOS CLIENTES | R18: 70994.15
A19: 749 | D19: 3.1.1.04.0749 | I19: FRETES COBRADOS DOS CLIENTES | R19: 70994.15
H20: RECEITA OPERACIONAL TOTAL | R20: 1175012.1
H22: CUSTO DOS PRODUTOS VENDIDOS (CPV/CMV) | R22: -418644.32
A23: 162 | D23: 3.7.1.01.0162 | I23: CUSTO DAS MERCADORIAS VENDIDAS | R23: -315364.95
A24: 165 | D24: 3.7.1.01.0165 | I24: DIREITOS AUTORAIS | R24: -73809.99
A25: 170 | D25: 3.7.1.01.0170 | I25: ROYALTIES EDITORIAIS E OUTROS | R25: -29469.38
H26: TOTAL CUSTO DOS PRODUTOS VENDIDOS | R26: -418644.32
H28: RECEITAS FINANCEIRAS | R28: 5.05
A29: 135 | D29: 3.2.1.01.0135 | I29: FUNDOS DIVERSOS | R29: 5.05
H30: OUTRAS RECEITAS | R30: 646.12
A31: 159 | D31: 3.3.1.01.0159 | I31: OUTRAS RECEITAS | R31: 646.12
H32: LUCRO BRUTO | R32: 757019
H34: DESPESAS VARIÁVEIS COMERCIAIS | R34: -99850.61
A35: 164 | D35: 3.7.1.01.0164 | I35: FRETES SOBRE MERCADORIAS | R35: -57419.4
A36: 206 | D36: 4.1.1.05.0206 | I36: COMISSOES POR VENDA | R36: -3885.76
A37: 207 | D37: 4.1.1.05.0207 | I37: BONUS POR RESULTADO | R37: -5430.92
A38: 224 | D38: 4.3.1.01.0224 | I38: EMBALAGENS E MATERIAS GRAFICOS | R38: -33114.53
H39: TAXA DE CARTAO / GATEWAY | R39: -82349.2
A40: 250 | D40: 4.3.1.03.0250 | I40: DESPESAS PAGAR ME | R40: -18860.63
A41: 253 | D41: 4.3.1.03.0253 | I41: DESPESAS MERCADO PAGO.COM | R41: -53682.39
A42: 651 | D42: 4.3.1.03.0651 | I42: DESPESAS AMAZON | R42: -9742.64
A43: 653 | D43: 4.3.1.03.0653 | I43: DESPESAS STONE | R43: -63.54
H44: TOTAL DESPESAS VARIÁVEIS COMERCIAIS | R44: -182199.81
H46: MARGEM DE CONTRIBUIÇÃO | R46: 574819.19
...

Sheet 2025
A1: Código | D1: Classificação | H1: Descrição | R1: Saldo Atual
H2: RECEITA COM VENDAS | R2: 5890772.5
A3: 860 | D3: 3.1.1.03.0860 | I3: ATACADO | R3: 1761432.2
A4: 861 | D4: 3.1.1.03.0861 | I4: ECOMMERCE | R4: 2580276.4
A5: 862 | D5: 3.1.1.03.0862 | I5: EVENTO | R5: 223689.25
A6: 865 | D6: 3.1.1.03.0865 | I6: LIVRARIA | R6: 1308896.3
A7: 868 | D7: 3.1.1.03.0868 | I7: SHOWROOM | R7: 16478.36
H8: MARKETPLACES | R8: 729067.69
A9: 863 | D9: 3.1.1.03.0863 | I9: AMAZON | R9: 239275.09
A10: 864 | D10: 3.1.1.03.0864 | I10: MERCADO LIVRE | R10: 350577.52
A11: 866 | D11: 3.1.1.03.0866 | I11: FULL ML | R11: 123810.66
A12: 867 | D12: 3.1.1.03.0867 | I12: TIKTOK | R12: 98.92
A13: 869 | D13: 3.1.1.03.0869 | I13: AMAZON FULL | R13: 15305.5
H14: TOTAL RECEITA BRUTA COM VENDAS | R14: 6619840.2
H16: DEVOLUÇÃO E DESCONTO DE VENDAS | R16: -27576.85
A17: 166 | D17: 3.6.1.01.0166 | I17: DEVOLUCAO DE VENDAS | R17: -27555.05
A18: 168 | D18: 3.6.1.01.0168 | I18: DESCONTO SOBRE VENDAS | R18: -21.8
H19: RECEITA LÍQUIDA DE VENDAS | R19: 6592263.3
H21: FRETE COBRADO DOS CLIENTES | R21: 401312.24
A22: 749 | D22: 3.1.1.04.0749 | I22: FRETES COBRADOS DOS CLIENTES | R22: 401312.24
H23: RECEITA OPERACIONAL TOTAL | R23: 6993575.6
H25: CUSTO DOS PRODUTOS VENDIDOS (CPV/CMV) | R25: -2656876.1
A26: 162 | D26: 3.7.1.01.0162 | I26: CUSTO DAS MERCADORIAS VENDIDAS | R26: -2090405.1
A27: 165 | D27: 3.7.1.01.0165 | I27: DIREITOS AUTORAIS | R27: -270568.5
A28: 167 | D28: 3.7.1.01.0167 | I28: MATERIAIS APLICADOS NA VENDA DE PRODUTOS | R28: -16737.42
A29: 170 | D29: 3.7.1.01.0170 | I29: ROYALTIES EDITORIAIS E OUTROS | R29: -279165.03
H30: TOTAL CUSTO DOS PRODUTOS VENDIDOS | R30: -2656876.1
H32: RECEITAS FINANCEIRAS | R32: 28.56
A33: 135 | D33: 3.2.1.01.0135 | I33: FUNDOS DIVERSOS | R33: 28.56
H34: OUTRAS RECEITAS | R34: 6733.65
A35: 159 | D35: 3.3.1.01.0159 | I35: OUTRAS RECEITAS | R35: 6733.65
H36: LUCRO BRUTO | R36: 4343461.7
H38: DESPESAS VARIÁVEIS COMERCIAIS | R38: -535682.71
A39: 164 | D39: 3.7.1.01.0164 | I39: FRETES SOBRE MERCADORIAS | R39: -396817.05
A40: 206 | D40: 4.1.1.05.0206 | I40: COMISSOES POR VENDA | R40: -33190.26
A41: 207 | D41: 4.1.1.05.0207 | I41: BONUS POR RESULTADO | R41: -47826.21
A42: 212 | D42: 4.3.1.01.0212 | I42: DESPESAS REPRESENTACAO COMERCIAL | R42: -1824.94
A43: 224 | D43: 4.3.1.01.0224 | I43: EMBALAGENS E MATERIAS GRAFICOS | R43: -56024.25
H44: TAXA DE CARTAO / GATEWAY | R44: -290072.56
A45: 250 | D45: 4.3.1.03.0250 | I45: DESPESAS PAGAR ME | R45: -42242.28
...

Sheet Planilha13
A1: Código | D1: Classificação | H1: Descrição | R1: Saldo Atual
H2: RECEITA COM VENDAS | R2: 689636.36
A3: 860 | D3: 3.1.1.03.0860 | I3: ATACADO | R3: 296951.19
A4: 861 | D4: 3.1.1.03.0861 | I4: ECOMMERCE | R4: 301545.85
A5: 865 | D5: 3.1.1.03.0865 | I5: LIVRARIA | R5: 90172.44
A6: 868 | D6: 3.1.1.03.0868 | I6: SHOWROOM | R6: 966.88
H7: MARKETPLACES | R7: 191702.95
A8: 863 | D8: 3.1.1.03.0863 | I8: AMAZON | R8: 74979.08
A9: 864 | D9: 3.1.1.03.0864 | I9: MERCADO LIVRE | R9: 108716.92
A10: 866 | D10: 3.1.1.03.0866 | I10: FULL ML | R10: 2193.35
A11: 869 | D11: 3.1.1.03.0869 | I11: AMAZON FULL | R11: 5813.6
H12: TOTAL RECEITA BRUTA COM VENDAS | R12: 881339.31
H14: DEVOLUÇÃO E DESCONTO DE VENDAS | R14: -5995.25
A15: 166 | D15: 3.6.1.01.0166 | I15: DEVOLUCAO DE VENDAS | R15: -5995.25
H16: RECEITA LÍQUIDA DE VENDAS | R16: 875344.06
H18: FRETE COBRADO DOS CLIENTES | R18: 57972.3
A19: 749 | D19: 3.1.1.04.0749 | I19: FRETES COBRADOS DOS CLIENTES | R19: 57972.3
H20: RECEITA OPERACIONAL TOTAL | R20: 933316.36
H22: CUSTO DOS PRODUTOS VENDIDOS (CPV/CMV) | R22: -323061.98
A23: 162 | D23: 3.7.1.01.0162 | I23: CUSTO DAS MERCADORIAS VENDIDAS | R23: -224504.78
A24: 165 | D24: 3.7.1.01.0165 | I24: DIREITOS AUTORAIS | R24: -55662.56
A25: 170 | D25: 3.7.1.01.0170 | I25: ROYALTIES EDITORIAIS E OUTROS | R25: -42894.64
H26: TOTAL CUSTO DOS PRODUTOS VENDIDOS | R26: -323061.98
H28: RECEITAS FINANCEIRAS | R28: 40.59
A29: 135 | D29: 3.2.1.01.0135 | I29: FUNDOS DIVERSOS | R29: 40.59
H30: OUTRAS RECEITAS | R30: 1231.9
A31: 159 | D31: 3.3.1.01.0159 | I31: OUTRAS RECEITAS | R31: 1231.9
H32: LUCRO BRUTO | R32: 611526.87
H34: DESPESAS VARIÁVEIS COMERCIAIS | R34: -72234.57
A35: 164 | D35: 3.7.1.01.0164 | I35: FRETES SOBRE MERCADORIAS | R35: -55960.11
A36: 206 | D36: 4.1.1.05.0206 | I36: COMISSOES POR VENDA | R36: -7925.23
A37: 207 | D37: 4.1.1.05.0207 | I37: BONUS POR RESULTADO | R37: -450
A38: 224 | D38: 4.3.1.01.0224 | I38: EMBALAGENS E MATERIAS GRAFICOS | R38: -7899.23
H39: TAXA DE CARTAO / GATEWAY | R39: -80047.92
A40: 250 | D40: 4.3.1.03.0250 | I40: DESPESAS PAGAR ME | R40: -9629.75
A41: 253 | D41: 4.3.1.03.0253 | I41: DESPESAS MERCADO PAGO.COM | R41: -45119.27
A42: 651 | D42: 4.3.1.03.0651 | I42: DESPESAS AMAZON | R42: -21745.48
A43: 653 | D43: 4.3.1.03.0653 | I43: DESPESAS STONE | R43: -3553.42
H44: TOTAL DESPESAS VARIÁVEIS COMERCIAIS | R44: -152282.49
H46: MARGEM DE CONTRIBUIÇÃO | R46: 459244.38
...

Sheet Planilha14
A1: Código | D1: Classificação | H1: Descrição | R1: Saldo Atual
H2: RECEITA COM VENDAS | R2: 532921.71
A3: 860 | D3: 3.1.1.03.0860 | I3: ATACADO | R3: 196602.12
A4: 861 | D4: 3.1.1.03.0861 | I4: ECOMMERCE | R4: 211081.53
A5: 862 | D5: 3.1.1.03.0862 | I5: EVENTO | R5: 2312.7
A6: 865 | D6: 3.1.1.03.0865 | I6: LIVRARIA | R6: 121460.56
A7: 868 | D7: 3.1.1.03.0868 | I7: SHOWROOM | R7: 1464.8
H8: MARKETPLACES | R8: 115473.06
A9: 863 | D9: 3.1.1.03.0863 | I9: AMAZON | R9: 26276.33
A10: 864 | D10: 3.1.1.03.0864 | I10: MERCADO LIVRE | R10: 83583.13
A11: 866 | D11: 3.1.1.03.0866 | I11: FULL ML | R11: 1260.7
A12: 869 | D12: 3.1.1.03.0869 | I12: AMAZON FULL | R12: 4352.9
H13: TOTAL RECEITA BRUTA COM VENDAS | R13: 648394.77
H15: DEVOLUÇÃO E DESCONTO DE VENDAS | R15: -1321.6
A16: 166 | D16: 3.6.1.01.0166 | I16: DEVOLUCAO DE VENDAS | R16: -1321.6
H17: RECEITA LÍQUIDA DE VENDAS | R17: 647073.17
H19: FRETE COBRADO DOS CLIENTES | R19: 43241.57
A20: 749 | D20: 3.1.1.04.0749 | I20: FRETES COBRADOS DOS CLIENTES | R20: 43241.57
H21: RECEITA OPERACIONAL TOTAL | R21: 690314.74
H23: CUSTO DOS PRODUTOS VENDIDOS (CPV/CMV) | R23: -268554.6
A24: 162 | D24: 3.7.1.01.0162 | I24: CUSTO DAS MERCADORIAS VENDIDAS | R24: -226388.73
A25: 165 | D25: 3.7.1.01.0165 | I25: DIREITOS AUTORAIS | R25: -24922.51
A26: 170 | D26: 3.7.1.01.0170 | I26: ROYALTIES EDITORIAIS E OUTROS | R26: -17243.36
H27: TOTAL CUSTO DOS PRODUTOS VENDIDOS | R27: -268554.6
H29: RECEITAS FINANCEIRAS | R29: 12.69
A30: 135 | D30: 3.2.1.01.0135 | I30: FUNDOS DIVERSOS | R30: 12.69
H31: OUTRAS RECEITAS | R31: 1831.47
A32: 159 | D32: 3.3.1.01.0159 | I32: OUTRAS RECEITAS | R32: 1831.47
H33: LUCRO BRUTO | R33: 423604.3
H35: DESPESAS VARIÁVEIS COMERCIAIS | R35: -41897.45
A36: 164 | D36: 3.7.1.01.0164 | I36: FRETES SOBRE MERCADORIAS | R36: -37902.87
A37: 206 | D37: 4.1.1.05.0206 | I37: COMISSOES POR VENDA | R37: -1397.61
A38: 207 | D38: 4.1.1.05.0207 | I38: BONUS POR RESULTADO | R38: -450
A39: 224 | D39: 4.3.1.01.0224 | I39: EMBALAGENS E MATERIAS GRAFICOS | R39: -2146.97
H40: TAXA DE CARTAO / GATEWAY | R40: -47957.89
A41: 250 | D41: 4.3.1.03.0250 | I41: DESPESAS PAGAR ME | R41: -7748.07
A42: 253 | D42: 4.3.1.03.0253 | I42: DESPESAS MERCADO PAGO.COM | R42: -24656.73
A43: 651 | D43: 4.3.1.03.0651 | I43: DESPESAS AMAZON | R43: -10705.12
A44: 653 | D44: 4.3.1.03.0653 | I44: DESPESAS STONE | R44: -4847.97
H45: TOTAL DESPESAS VARIÁVEIS COMERCIAIS | R45: -89855.34
...

Sheet 2026
A1: Código | D1: Classificação | H1: Descrição | R1: Saldo Atual
H2: RECEITA COM VENDAS | R2: 1222558.1
A3: 860 | D3: 3.1.1.03.0860 | I3: ATACADO | R3: 493553.31
A4: 861 | D4: 3.1.1.03.0861 | I4: ECOMMERCE | R4: 512627.38
A5: 862 | D5: 3.1.1.03.0862 | I5: EVENTO | R5: 2312.7
A6: 865 | D6: 3.1.1.03.0865 | I6: LIVRARIA | R6: 211633
A7: 868 | D7: 3.1.1.03.0868 | I7: SHOWROOM | R7: 2431.68
H8: MARKETPLACES | R8: 307176.01
A9: 863 | D9: 3.1.1.03.0863 | I9: AMAZON | R9: 101255.41
A10: 864 | D10: 3.1.1.03.0864 | I10: MERCADO LIVRE | R10: 192300.05
A11: 866 | D11: 3.1.1.03.0866 | I11: FULL ML | R11: 3454.05
A12: 869 | D12: 3.1.1.03.0869 | I12: AMAZON FULL | R12: 10166.5
H13: TOTAL RECEITA BRUTA COM VENDAS | R13: 1529734.1
H15: DEVOLUÇÃO E DESCONTO DE VENDAS | R15: -7316.85
A16: 166 | D16: 3.6.1.01.0166 | I16: DEVOLUCAO DE VENDAS | R16: -7316.85
H17: RECEITA LÍQUIDA DE VENDAS | R17: 1522417.2
H19: FRETE COBRADO DOS CLIENTES | R19: 101213.87
A20: 749 | D20: 3.1.1.04.0749 | I20: FRETES COBRADOS DOS CLIENTES | R20: 101213.87
H21: RECEITA OPERACIONAL TOTAL | R21: 1623631.1
H23: CUSTO DOS PRODUTOS VENDIDOS (CPV/CMV) | R23: -591616.58
A24: 162 | D24: 3.7.1.01.0162 | I24: CUSTO DAS MERCADORIAS VENDIDAS | R24: -450893.51
A25: 165 | D25: 3.7.1.01.0165 | I25: DIREITOS AUTORAIS | R25: -80585.07
A26: 170 | D26: 3.7.1.01.0170 | I26: ROYALTIES EDITORIAIS E OUTROS | R26: -60138
H27: TOTAL CUSTO DOS PRODUTOS VENDIDOS | R27: -591616.58
H29: RECEITAS FINANCEIRAS | R29: 53.28
A30: 135 | D30: 3.2.1.01.0135 | I30: FUNDOS DIVERSOS | R30: 53.28
H31: OUTRAS RECEITAS | R31: 3063.37
A32: 159 | D32: 3.3.1.01.0159 | I32: OUTRAS RECEITAS | R32: 3063.37
H33: LUCRO BRUTO | R33: 1035131.2
H35: DESPESAS VARIÁVEIS COMERCIAIS | R35: -114132.02
A36: 164 | D36: 3.7.1.01.0164 | I36: FRETES SOBRE MERCADORIAS | R36: -93862.98
A37: 206 | D37: 4.1.1.05.0206 | I37: COMISSOES POR VENDA | R37: -9322.84
A38: 207 | D38: 4.1.1.05.0207 | I38: BONUS POR RESULTADO | R38: -900
A39: 224 | D39: 4.3.1.01.0224 | I39: EMBALAGENS E MATERIAS GRAFICOS | R39: -10046.2
H40: TAXA DE CARTAO / GATEWAY | R40: -128005.81
A41: 250 | D41: 4.3.1.03.0250 | I41: DESPESAS PAGAR ME | R41: -17377.82
A42: 253 | D42: 4.3.1.03.0253 | I42: DESPESAS MERCADO PAGO.COM | R42: -69776
A43: 651 | D43: 4.3.1.03.0651 | I43: DESPESAS AMAZON | R43: -32450.6
A44: 653 | D44: 4.3.1.03.0653 | I44: DESPESAS STONE | R44: -8401.39
H45: TOTAL DESPESAS VARIÁVEIS COMERCIAIS | R45: -242137.83
...

Sheet Relatorio
A1: Empresa: | D1: ASSOCIAÇÃO EDITORA PRESBITERIANA DE PINHEIROS | X1: Página: | Y1: 1
A2: C.N.P.J.: | D2: 40.804.477/0001-44
A4: DEMONSTRAÇÃO DO RESULTADO DO PERÍODO EM 2025
A6: Descrição | I6: 45658 | J6: 45689 | K6: 45717 | L6: 45748 | M6: 45778 | N6: 45809 | O6: 45839 | P6: 45870 | Q6: 45901 | R6: 45931 | S6: 45962 | T6: 45992 | V6: 46023 | W6: 46054 | Y6: 2026
A7: RECEITA COM VENDAS | I7: =SUMIF(Planilha1!$H$1:$H$110,A7,Planilha1!$R$1:$R$150) -> 495905.57 | J7: =SUMIF(Planilha2!$H$1:$H$110,A7,Planilha2!$R$1:$R$150) -> 418702.3 | K7: =SUMIF(Planilha3!$H$1:$H$110,A7,Planilha3!$R$1:$R$150) -> 467954.66 | L7: =SUMIF(Planilha4!$H$1:$H$110,A7,Planilha4!$R$1:$R$150) -> 388073.88 | M7: =SUMIF(Planilha5!$H$1:$H$110,A7,Planilha5!$R$1:$R$150) -> 503039.55 | N7: =SUMIF(Planilha6!$H$1:$H$110,A7,Planilha6!$R$1:$R$150) -> 347333.52 | O7: =SUMIF(Planilha7!$H$1:$H$110,A7,Planilha7!$R$1:$R$150) -> 316622.52 | P7: =SUMIF(Planilha8!$H$1:$H$110,A7,Planilha8!$R$1:$R$150) -> 393480.25 | Q7: =SUMIF(Planilha9!$H$1:$H$110,A7,Planilha9!$R$1:$R$150) -> 365887.99 | R7: =SUMIF(Planilha10!$H$1:$H$110,A7,Planilha10!$R$1:$R$150) -> 581307.37 | S7: =SUMIF(Planilha11!$H$1:$H$110,A7,Planilha11!$R$1:$R$150) -> 721066.96 | T7: =SUMIF(Planilha12!$H$1:$H$110,A7,Planilha12!$R$1:$R$150) -> 891397.91 | V7: =SUMIF(Planilha13!$H$1:$H$110,A7,Planilha13!$R$1:$R$150) -> 689636.36 | W7: =SUMIF(Planilha14!$H$1:$H$110,A7,Planilha14!$R$1:$R$150) -> 532921.71 | Y7: =SUMIF('2026'!$H$1:$H$110,A7,'2026'!$R$1:$R$150) -> 1222558.1 | Z7: =SUM(V7:W7)-Y7 -> 0
B8: ATACADO | I8: =SUMIF(Planilha1!$I$1:$I$150,B8,Planilha1!$R$1:RL$150) -> 254042.11 | J8: =SUMIF(Planilha2!$I$1:$I$150,B8,Planilha2!$R$1:RM$150) -> 164622.6 | K8: =SUMIF(Planilha3!$I$1:$I$150,B8,Planilha3!$R$1:RN$150) -> 193567.41 | L8: =SUMIF(Planilha4!$I$1:$I$150,B8,Planilha4!$R$1:RO$150) -> 132575.25 | M8: =SUMIF(Planilha5!$I$1:$I$150,B8,Planilha5!$R$1:RP$150) -> 219556.41 | N8: =SUMIF(Planilha6!$I$1:$I$150,B8,Planilha6!$R$1:RQ$150) -> 60852.57 | O8: =SUMIF(Planilha7!$I$1:$I$150,B8,Planilha7!$R$1:RR$150) -> 60934.28 | P8: =SUMIF(Planilha8!$I$1:$I$150,B8,Planilha8!$R$1:RS$150) -> 67772.31 | Q8: =SUMIF(Planilha9!$I$1:$I$150,B8,Planilha9!$R$1:RT$150) -> 119355.57 | R8: =SUMIF(Planilha10!$I$1:$I$150,B8,Planilha10!$R$1:RU$150) -> 103628.97 | S8: =SUMIF(Planilha11!$I$1:$I$150,B8,Planilha11!$R$1:RV$150) -> 81748.93 | T8: =SUMIF(Planilha12!$I$1:$I$150,B8,Planilha12!$R$1:RW$150) -> 302775.76 | V8: =SUMIF(Planilha13!$I$1:$I$150,B8,Planilha13!$R$1:RY$150) -> 296951.19 | W8: =SUMIF(Planilha14!$I$1:$I$150,B8,Planilha14!$R$1:RZ$150) -> 196602.12 | Y8: =SUMIF('2026'!$I$1:$I$150,B8,'2026'!$R$1:RQ$150) -> 493553.31 | Z8: =SUM(V8:W8)-Y8 -> 0
B9: ECOMMERCE | I9: =SUMIF(Planilha1!$I$1:$I$150,B9,Planilha1!$R$1:RL$150) -> 163266.31 | J9: =SUMIF(Planilha2!$I$1:$I$150,B9,Planilha2!$R$1:RM$150) -> 128055.93 | K9: =SUMIF(Planilha3!$I$1:$I$150,B9,Planilha3!$R$1:RN$150) -> 164134.17 | L9: =SUMIF(Planilha4!$I$1:$I$150,B9,Planilha4!$R$1:RO$150) -> 161518.87 | M9: =SUMIF(Planilha5!$I$1:$I$150,B9,Planilha5!$R$1:RP$150) -> 167517.93 | N9: =SUMIF(Planilha6!$I$1:$I$150,B9,Planilha6!$R$1:RQ$150) -> 173821.57 | O9: =SUMIF(Planilha7!$I$1:$I$150,B9,Planilha7!$R$1:RR$150) -> 158614.03 | P9: =SUMIF(Planilha8!$I$1:$I$150,B9,Planilha8!$R$1:RS$150) -> 183185.27 | Q9: =SUMIF(Planilha9!$I$1:$I$150,B9,Planilha9!$R$1:RT$150) -> 128905.32 | R9: =SUMIF(Planilha10!$I$1:$I$150,B9,Planilha10!$R$1:RU$150) -> 362077.95 | S9: =SUMIF(Planilha11!$I$1:$I$150,B9,Planilha11!$R$1:RV$150) -> 337371.61 | T9: =SUMIF(Planilha12!$I$1:$I$150,B9,Planilha12!$R$1:RW$150) -> 451807.46 | V9: =SUMIF(Planilha13!$I$1:$I$150,B9,Planilha13!$R$1:RY$150) -> 301545.85 | W9: =SUMIF(Planilha14!$I$1:$I$150,B9,Planilha14!$R$1:RZ$150) -> 211081.53 | Y9: =SUMIF('2026'!$I$1:$I$150,B9,'2026'!$R$1:RQ$150) -> 512627.38 | Z9: =SUM(V9:W9)-Y9 -> 0
B10: EVENTO | I10: =SUMIF(Planilha1!$I$1:$I$150,B10,Planilha1!$R$1:RL$150) -> 0 | J10: =SUMIF(Planilha2!$I$1:$I$150,B10,Planilha2!$R$1:RM$150) -> 47047.21 | K10: =SUMIF(Planilha3!$I$1:$I$150,B10,Planilha3!$R$1:RN$150) -> 20118.81 | L10: =SUMIF(Planilha4!$I$1:$I$150,B10,Planilha4!$R$1:RO$150) -> 1613.05 | M10: =SUMIF(Planilha5!$I$1:$I$150,B10,Planilha5!$R$1:RP$150) -> 2953.61 | N10: =SUMIF(Planilha6!$I$1:$I$150,B10,Planilha6!$R$1:RQ$150) -> 4466.5 | O10: =SUMIF(Planilha7!$I$1:$I$150,B10,Planilha7!$R$1:RR$150) -> 193.79 | P10: =SUMIF(Planilha8!$I$1:$I$150,B10,Planilha8!$R$1:RS$150) -> 5920.9 | Q10: =SUMIF(Planilha9!$I$1:$I$150,B10,Planilha9!$R$1:RT$150) -> 2022.62 | R10: =SUMIF(Planilha10!$I$1:$I$150,B10,Planilha10!$R$1:RU$150) -> 0 | S10: =SUMIF(Planilha11!$I$1:$I$150,B10,Planilha11!$R$1:RV$150) -> 139352.76 | T10: =SUMIF(Planilha12!$I$1:$I$150,B10,Planilha12!$R$1:RW$150) -> 0 | V10: =SUMIF(Planilha13!$I$1:$I$150,B10,Planilha13!$R$1:RY$150) -> 0 | W10: =SUMIF(Planilha14!$I$1:$I$150,B10,Planilha14!$R$1:RZ$150) -> 2312.7 | Y10: =SUMIF('2026'!$I$1:$I$150,B10,'2026'!$R$1:RQ$150) -> 2312.7 | Z10: =SUM(V10:W10)-Y10 -> 0
B11: LIVRARIA | I11: =SUMIF(Planilha1!$I$1:$I$150,B11,Planilha1!$R$1:RL$150) -> 78597.15 | J11: =SUMIF(Planilha2!$I$1:$I$150,B11,Planilha2!$R$1:RM$150) -> 78976.56 | K11: =SUMIF(Planilha3!$I$1:$I$150,B11,Planilha3!$R$1:RN$150) -> 90134.27 | L11: =SUMIF(Planilha4!$I$1:$I$150,B11,Planilha4!$R$1:RO$150) -> 92366.71 | M11: =SUMIF(Planilha5!$I$1:$I$150,B11,Planilha5!$R$1:RP$150) -> 113011.6 | N11: =SUMIF(Planilha6!$I$1:$I$150,B11,Planilha6!$R$1:RQ$150) -> 108192.88 | O11: =SUMIF(Planilha7!$I$1:$I$150,B11,Planilha7!$R$1:RR$150) -> 96573.67 | P11: =SUMIF(Planilha8!$I$1:$I$150,B11,Planilha8!$R$1:RS$150) -> 132362.67 | Q11: =SUMIF(Planilha9!$I$1:$I$150,B11,Planilha9!$R$1:RT$150) -> 108371.46 | R11: =SUMIF(Planilha10!$I$1:$I$150,B11,Planilha10!$R$1:RU$150) -> 114754.37 | S11: =SUMIF(Planilha11!$I$1:$I$150,B11,Planilha11!$R$1:RV$150) -> 159575.85 | T11: =SUMIF(Planilha12!$I$1:$I$150,B11,Planilha12!$R$1:RW$150) -> 135979.09 | V11: =SUMIF(Planilha13!$I$1:$I$150,B11,Planilha13!$R$1:RY$150) -> 90172.44 | W11: =SUMIF(Planilha14!$I$1:$I$150,B11,Planilha14!$R$1:RZ$150) -> 121460.56 | Y11: =SUMIF('2026'!$I$1:$I$150,B11,'2026'!$R$1:RQ$150) -> 211633 | Z11: =SUM(V11:W11)-Y11 -> 0
B12: SHOWROOM | I12: =SUMIF(Planilha1!$I$1:$I$150,B12,Planilha1!$R$1:RL$150) -> 0 | J12: =SUMIF(Planilha2!$I$1:$I$150,B12,Planilha2!$R$1:RM$150) -> 0 | K12: =SUMIF(Planilha3!$I$1:$I$150,B12,Planilha3!$R$1:RN$150) -> 0 | L12: =SUMIF(Planilha4!$I$1:$I$150,B12,Planilha4!$R$1:RO$150) -> 0 | M12: =SUMIF(Planilha5!$I$1:$I$150,B12,Planilha5!$R$1:RP$150) -> 0 | N12: =SUMIF(Planilha6!$I$1:$I$150,B12,Planilha6!$R$1:RQ$150) -> 0 | O12: =SUMIF(Planilha7!$I$1:$I$150,B12,Planilha7!$R$1:RR$150) -> 306.75 | P12: =SUMIF(Planilha8!$I$1:$I$150,B12,Planilha8!$R$1:RS$150) -> 4239.1 | Q12: =SUMIF(Planilha9!$I$1:$I$150,B12,Planilha9!$R$1:RT$150) -> 7233.02 | R12: =SUMIF(Planilha10!$I$1:$I$150,B12,Planilha10!$R$1:RU$150) -> 846.08 | S12: =SUMIF(Planilha11!$I$1:$I$150,B12,Planilha11!$R$1:RV$150) -> 3017.81 | T12: =SUMIF(Planilha12!$I$1:$I$150,B12,Planilha12!$R$1:RW$150) -> 835.6 | V12: =SUMIF(Planilha13!$I$1:$I$150,B12,Planilha13!$R$1:RY$150) -> 966.88 | W12: =SUMIF(Planilha14!$I$1:$I$150,B12,Planilha14!$R$1:RZ$150) -> 1464.8 | Y12: =SUMIF('2026'!$I$1:$I$150,B12,'2026'!$R$1:RQ$150) -> 2431.68 | Z12: =SUM(V12:W12)-Y12 -> 0
A13: MARKETPLACES | I13: =SUMIF(Planilha1!$H$1:$H$110,A13,Planilha1!$R$1:$R$150) -> 13298.19 | J13: =SUMIF(Planilha2!$H$1:$H$110,A13,Planilha2!$R$1:$R$150) -> 4630.01 | K13: =SUMIF(Planilha3!$H$1:$H$110,A13,Planilha3!$R$1:$R$150) -> 28379.02 | L13: =SUMIF(Planilha4!$H$1:$H$110,A13,Planilha4!$R$1:$R$150) -> 22410.2 | M13: =SUMIF(Planilha5!$H$1:$H$110,A13,Planilha5!$R$1:$R$150) -> 14548.79 | N13: =SUMIF(Planilha6!$H$1:$H$110,A13,Planilha6!$R$1:$R$150) -> 32617.49 | O13: =SUMIF(Planilha7!$H$1:$H$110,A13,Planilha7!$R$1:$R$150) -> 52521.49 | P13: =SUMIF(Planilha8!$H$1:$H$110,A13,Planilha8!$R$1:$R$150) -> 102348.89 | Q13: =SUMIF(Planilha9!$H$1:$H$110,A13,Planilha9!$R$1:$R$150) -> 76825.93 | R13: =SUMIF(Planilha10!$H$1:$H$110,A13,Planilha10!$R$1:$R$150) -> 66278.9 | S13: =SUMIF(Planilha11!$H$1:$H$110,A13,Planilha11!$R$1:$R$150) -> 97895.65 | T13: =SUMIF(Planilha12!$H$1:$H$110,A13,Planilha12!$R$1:$R$150) -> 217313.13 | V13: =SUMIF(Planilha13!$H$1:$H$110,A13,Planilha13!$R$1:$R$150) -> 191702.95 | W13: =SUMIF(Planilha14!$H$1:$H$110,A13,Planilha14!$R$1:$R$150) -> 115473.06 | Y13: =SUMIF('2026'!$H$1:$H$110,A13,'2026'!$R$1:$R$150) -> 307176.01 | Z13: =SUM(V13:W13)-Y13 -> 0
B14: AMAZON | I14: =SUMIF(Planilha1!$I$1:$I$150,B14,Planilha1!$R$1:RL$150) -> 11612.4 | J14: =SUMIF(Planilha2!$I$1:$I$150,B14,Planilha2!$R$1:RM$150) -> 1393.5 | K14: =SUMIF(Planilha3!$I$1:$I$150,B14,Planilha3!$R$1:RN$150) -> 22701.73 | L14: =SUMIF(Planilha4!$I$1:$I$150,B14,Planilha4!$R$1:RO$150) -> 19863 | M14: =SUMIF(Planilha5!$I$1:$I$150,B14,Planilha5!$R$1:RP$150) -> 11019.65 | N14: =SUMIF(Planilha6!$I$1:$I$150,B14,Planilha6!$R$1:RQ$150) -> 11271.66 | O14: =SUMIF(Planilha7!$I$1:$I$150,B14,Planilha7!$R$1:RR$150) -> 5295.83 | P14: =SUMIF(Planilha8!$I$1:$I$150,B14,Planilha8!$R$1:RS$150) -> 12708.58 | Q14: =SUMIF(Planilha9!$I$1:$I$150,B14,Planilha9!$R$1:RT$150) -> 14195.45 | R14: =SUMIF(Planilha10!$I$1:$I$150,B14,Planilha10!$R$1:RU$150) -> 23873.87 | S14: =SUMIF(Planilha11!$I$1:$I$150,B14,Planilha11!$R$1:RV$150) -> 43014.56 | T14: =SUMIF(Planilha12!$I$1:$I$150,B14,Planilha12!$R$1:RW$150) -> 62324.86 | V14: =SUMIF(Planilha13!$I$1:$I$150,B14,Planilha13!$R$1:RY$150) -> 74979.08 | W14: =SUMIF(Planilha14!$I$1:$I$150,B14,Planilha14!$R$1:RZ$150) -> 26276.33 | Y14: =SUMIF('2026'!$I$1:$I$150,B14,'2026'!$R$1:RQ$150) -> 101255.41 | Z14: =SUM(V14:W14)-Y14 -> 0
B15: AMAZON FULL | I15: =SUMIF(Planilha1!$I$1:$I$150,B15,Planilha1!$R$1:RL$150) -> 0 | J15: =SUMIF(Planilha2!$I$1:$I$150,B15,Planilha2!$R$1:RM$150) -> 0 | K15: =SUMIF(Planilha3!$I$1:$I$150,B15,Planilha3!$R$1:RN$150) -> 0 | L15: =SUMIF(Planilha4!$I$1:$I$150,B15,Planilha4!$R$1:RO$150) -> 0 | M15: =SUMIF(Planilha5!$I$1:$I$150,B15,Planilha5!$R$1:RP$150) -> 0 | N15: =SUMIF(Planilha6!$I$1:$I$150,B15,Planilha6!$R$1:RQ$150) -> 0 | O15: =SUMIF(Planilha7!$I$1:$I$150,B15,Planilha7!$R$1:RR$150) -> 0 | P15: =SUMIF(Planilha8!$I$1:$I$150,B15,Planilha8!$R$1:RS$150) -> 5694 | Q15: =SUMIF(Planilha9!$I$1:$I$150,B15,Planilha9!$R$1:RT$150) -> 3145.7 | R15: =SUMIF(Planilha10!$I$1:$I$150,B15,Planilha10!$R$1:RU$150) -> 3145.7 | S15: =SUMIF(Planilha11!$I$1:$I$150,B15,Planilha11!$R$1:RV$150) -> 1229.1 | T15: =SUMIF(Planilha12!$I$1:$I$150,B15,Planilha12!$R$1:RW$150) -> 2091 | V15: =SUMIF(Planilha13!$I$1:$I$150,B15,Planilha13!$R$1:RY$150) -> 5813.6 | W15: =SUMIF(Planilha14!$I$1:$I$150,B15,Planilha14!$R$1:RZ$150) -> 4352.9 | Y15: =SUMIF('2026'!$I$1:$I$150,B15,'2026'!$R$1:RQ$150) -> 10166.5 | Z15: =SUM(V15:W15)-Y15 -> 0
B16: MERCADO LIVRE | I16: =SUMIF(Planilha1!$I$1:$I$150,B16,Planilha1!$R$1:RL$150) -> 1685.79 | J16: =SUMIF(Planilha2!$I$1:$I$150,B16,Planilha2!$R$1:RM$150) -> 3236.51 | K16: =SUMIF(Planilha3!$I$1:$I$150,B16,Planilha3!$R$1:RN$150) -> 5677.29 | L16: =SUMIF(Planilha4!$I$1:$I$150,B16,Planilha4!$R$1:RO$150) -> 2547.2 | M16: =SUMIF(Planilha5!$I$1:$I$150,B16,Planilha5!$R$1:RP$150) -> 3529.14 | N16: =SUMIF(Planilha6!$I$1:$I$150,B16,Planilha6!$R$1:RQ$150) -> 18965.25 | O16: =SUMIF(Planilha7!$I$1:$I$150,B16,Planilha7!$R$1:RR$150) -> 26286.41 | P16: =SUMIF(Planilha8!$I$1:$I$150,B16,Planilha8!$R$1:RS$150) -> 56458.35 | Q16: =SUMIF(Planilha9!$I$1:$I$150,B16,Planilha9!$R$1:RT$150) -> 36501 | R16: =SUMIF(Planilha10!$I$1:$I$150,B16,Planilha10!$R$1:RU$150) -> 17237.34 | S16: =SUMIF(Planilha11!$I$1:$I$150,B16,Planilha11!$R$1:RV$150) -> 34575.46 | T16: =SUMIF(Planilha12!$I$1:$I$150,B16,Planilha12!$R$1:RW$150) -> 143877.78 | V16: =SUMIF(Planilha13!$I$1:$I$150,B16,Planilha13!$R$1:RY$150) -> 108716.92 | W16: =SUMIF(Planilha14!$I$1:$I$150,B16,Planilha14!$R$1:RZ$150) -> 83583.13 | Y16: =SUMIF('2026'!$I$1:$I$150,B16,'2026'!$R$1:RQ$150) -> 192300.05 | Z16: =SUM(V16:W16)-Y16 -> 0
B17: FULL ML | I17: =SUMIF(Planilha1!$I$1:$I$150,B17,Planilha1!$R$1:RL$150) -> 0 | J17: =SUMIF(Planilha2!$I$1:$I$150,B17,Planilha2!$R$1:RM$150) -> 0 | K17: =SUMIF(Planilha3!$I$1:$I$150,B17,Planilha3!$R$1:RN$150) -> 0 | L17: =SUMIF(Planilha4!$I$1:$I$150,B17,Planilha4!$R$1:RO$150) -> 0 | M17: =SUMIF(Planilha5!$I$1:$I$150,B17,Planilha5!$R$1:RP$150) -> 0 | N17: =SUMIF(Planilha6!$I$1:$I$150,B17,Planilha6!$R$1:RQ$150) -> 2281.66 | O17: =SUMIF(Planilha7!$I$1:$I$150,B17,Planilha7!$R$1:RR$150) -> 20939.25 | P17: =SUMIF(Planilha8!$I$1:$I$150,B17,Planilha8!$R$1:RS$150) -> 27487.96 | Q17: =SUMIF(Planilha9!$I$1:$I$150,B17,Planilha9!$R$1:RT$150) -> 22983.78 | R17: =SUMIF(Planilha10!$I$1:$I$150,B17,Planilha10!$R$1:RU$150) -> 22021.99 | S17: =SUMIF(Planilha11!$I$1:$I$150,B17,Planilha11!$R$1:RV$150) -> 19076.53 | T17: =SUMIF(Planilha12!$I$1:$I$150,B17,Planilha12!$R$1:RW$150) -> 9019.49 | V17: =SUMIF(Planilha13!$I$1:$I$150,B17,Planilha13!$R$1:RY$150) -> 2193.35 | W17: =SUMIF(Planilha14!$I$1:$I$150,B17,Planilha14!$R$1:RZ$150) -> 1260.7 | Y17: =SUMIF('2026'!$I$1:$I$150,B17,'2026'!$R$1:RQ$150) -> 3454.05 | Z17: =SUM(V17:W17)-Y17 -> 0
B18: TIKTOK | I18: =SUMIF(Planilha1!$I$1:$I$150,B18,Planilha1!$R$1:RL$150) -> 0 | J18: =SUMIF(Planilha2!$I$1:$I$150,B18,Planilha2!$R$1:RM$150) -> 0 | K18: =SUMIF(Planilha3!$I$1:$I$150,B18,Planilha3!$R$1:RN$150) -> 0 | L18: =SUMIF(Planilha4!$I$1:$I$150,B18,Planilha4!$R$1:RO$150) -> 0 | M18: =SUMIF(Planilha5!$I$1:$I$150,B18,Planilha5!$R$1:RP$150) -> 0 | N18: =SUMIF(Planilha6!$I$1:$I$150,B18,Planilha6!$R$1:RQ$150) -> 98.92 | O18: =SUMIF(Planilha7!$I$1:$I$150,B18,Planilha7!$R$1:RR$150) -> 0 | P18: =SUMIF(Planilha8!$I$1:$I$150,B18,Planilha8!$R$1:RS$150) -> 0 | Q18: =SUMIF(Planilha9!$I$1:$I$150,B18,Planilha9!$R$1:RT$150) -> 0 | R18: =SUMIF(Planilha10!$I$1:$I$150,B18,Planilha10!$R$1:RU$150) -> 0 | S18: =SUMIF(Planilha11!$I$1:$I$150,B18,Planilha11!$R$1:RV$150) -> 0 | T18: =SUMIF(Planilha12!$I$1:$I$150,B18,Planilha12!$R$1:RW$150) -> 0 | V18: =SUMIF(Planilha13!$I$1:$I$150,B18,Planilha13!$R$1:RY$150) -> 0 | W18: =SUMIF(Planilha14!$I$1:$I$150,B18,Planilha14!$R$1:RZ$150) -> 0 | Y18: =SUMIF('2026'!$I$1:$I$150,B18,'2026'!$R$1:RQ$150) -> 0 | Z18: =SUM(V18:W18)-Y18 -> 0
A19: TOTAL RECEITA BRUTA COM VENDAS | I19: =SUMIF(Planilha1!$H$1:$H$110,A19,Planilha1!$R$1:$R$150) -> 509203.76 | J19: =SUMIF(Planilha2!$H$1:$H$110,A19,Planilha2!$R$1:$R$150) -> 423332.31 | K19: =SUMIF(Planilha3!$H$1:$H$110,A19,Planilha3!$R$1:$R$150) -> 496333.68 | L19: =SUMIF(Planilha4!$H$1:$H$110,A19,Planilha4!$R$1:$R$150) -> 410484.08 | M19: =SUMIF(Planilha5!$H$1:$H$110,A19,Planilha5!$R$1:$R$150) -> 517588.34 | N19: =SUMIF(Planilha6!$H$1:$H$110,A19,Planilha6!$R$1:$R$150) -> 379951.01 | O19: =SUMIF(Planilha7!$H$1:$H$110,A19,Planilha7!$R$1:$R$150) -> 369144.01 | P19: =SUMIF(Planilha8!$H$1:$H$110,A19,Planilha8!$R$1:$R$150) -> 495829.14 | Q19: =SUMIF(Planilha9!$H$1:$H$110,A19,Planilha9!$R$1:$R$150) -> 442713.92 | R19: =SUMIF(Planilha10!$H$1:$H$110,A19,Planilha10!$R$1:$R$150) -> 647586.27 | S19: =SUMIF(Planilha11!$H$1:$H$110,A19,Planilha11!$R$1:$R$150) -> 818962.61 | T19: =SUMIF(Planilha12!$H$1:$H$110,A19,Planilha12!$R$1:$R$150) -> 1108711 | V19: =SUMIF(Planilha13!$H$1:$H$110,A19,Planilha13!$R$1:$R$150) -> 881339.31 | W19: =SUMIF(Planilha14!$H$1:$H$110,A19,Planilha14!$R$1:$R$150) -> 648394.77 | Y19: =SUMIF('2026'!$H$1:$H$110,A19,'2026'!$R$1:$R$150) -> 1529734.1 | Z19: =SUM(V19:W19)-Y19 -> 0
Z20: =SUM(V20:W20)-Y20 -> 0
A21: DEVOLUÇÃO E DESCONTO DE VENDAS | I21: =SUMIF(Planilha1!$H$1:$H$110,A21,Planilha1!$R$1:$R$150) -> -318.25 | J21: =SUMIF(Planilha2!$H$1:$H$110,A21,Planilha2!$R$1:$R$150) -> -743.82 | K21: =SUMIF(Planilha3!$H$1:$H$110,A21,Planilha3!$R$1:$R$150) -> -109.63 | L21: =SUMIF(Planilha4!$H$1:$H$110,A21,Planilha4!$R$1:$R$150) -> -967.46 | M21: =SUMIF(Planilha5!$H$1:$H$110,A21,Planilha5!$R$1:$R$150) -> -569.8 | N21: =SUMIF(Planilha6!$H$1:$H$110,A21,Planilha6!$R$1:$R$150) -> -1607.93 | O21: =SUMIF(Planilha7!$H$1:$H$110,A21,Planilha7!$R$1:$R$150) -> -3996.41 | P21: =SUMIF(Planilha8!$H$1:$H$110,A21,Planilha8!$R$1:$R$150) -> -4964.76 | Q21: =SUMIF(Planilha9!$H$1:$H$110,A21,Planilha9!$R$1:$R$150) -> -5299.1 | R21: =SUMIF(Planilha10!$H$1:$H$110,A21,Planilha10!$R$1:$R$150) -> -1467.16 | S21: =SUMIF(Planilha11!$H$1:$H$110,A21,Planilha11!$R$1:$R$150) -> -2839.49 | T21: =SUMIF(Planilha12!$H$1:$H$110,A21,Planilha12!$R$1:$R$150) -> -4693.04 | V21: =SUMIF(Planilha13!$H$1:$H$110,A21,Planilha13!$R$1:$R$150) -> -5995.25 | W21: =SUMIF(Planilha14!$H$1:$H$110,A21,Planilha14!$R$1:$R$150) -> -1321.6 | Y21: =SUMIF('2026'!$H$1:$H$110,A21,'2026'!$R$1:$R$150) -> -7316.85 | Z21: =SUM(V21:W21)-Y21 -> 0
B22: DEVOLUCAO DE VENDAS | I22: =SUMIF(Planilha1!$I$1:$I$150,B22,Planilha1!$R$1:RL$150) -> -296.45 | J22: =SUMIF(Planilha2!$I$1:$I$150,B22,Planilha2!$R$1:RM$150) -> -743.82 | K22: =SUMIF(Planilha3!$I$1:$I$150,B22,Planilha3!$R$1:RN$150) -> -109.63 | L22: =SUMIF(Planilha4!$I$1:$I$150,B22,Planilha4!$R$1:RO$150) -> -967.46 | M22: =SUMIF(Planilha5!$I$1:$I$150,B22,Planilha5!$R$1:RP$150) -> -569.8 | N22: =SUMIF(Planilha6!$I$1:$I$150,B22,Planilha6!$R$1:RQ$150) -> -1607.93 | O22: =SUMIF(Planilha7!$I$1:$I$150,B22,Planilha7!$R$1:RR$150) -> -3996.41 | P22: =SUMIF(Planilha8!$I$1:$I$150,B22,Planilha8!$R$1:RS$150) -> -4964.76 | Q22: =SUMIF(Planilha9!$I$1:$I$150,B22,Planilha9!$R$1:RT$150) -> -5299.1 | R22: =SUMIF(Planilha10!$I$1:$I$150,B22,Planilha10!$R$1:RU$150) -> -1467.16 | S22: =SUMIF(Planilha11!$I$1:$I$150,B22,Planilha11!$R$1:RV$150) -> -2839.49 | T22: =SUMIF(Planilha12!$I$1:$I$150,B22,Planilha12!$R$1:RW$150) -> -4693.04 | V22: =SUMIF(Planilha13!$I$1:$I$150,B22,Planilha13!$R$1:RY$150) -> -5995.25 | W22: =SUMIF(Planilha14!$I$1:$I$150,B22,Planilha14!$R$1:RZ$150) -> -1321.6 | Y22: =SUMIF('2026'!$I$1:$I$150,B22,'2026'!$R$1:RQ$150) -> -7316.85 | Z22: =SUM(V22:W22)-Y22 -> 0
B23: DESCONTO SOBRE VENDAS | I23: =SUMIF(Planilha1!$I$1:$I$150,B23,Planilha1!$R$1:RL$150) -> -21.8 | J23: =SUMIF(Planilha2!$I$1:$I$150,B23,Planilha2!$R$1:RM$150) -> 0 | K23: =SUMIF(Planilha3!$I$1:$I$150,B23,Planilha3!$R$1:RN$150) -> 0 | L23: =SUMIF(Planilha4!$I$1:$I$150,B23,Planilha4!$R$1:RO$150) -> 0 | M23: =SUMIF(Planilha5!$I$1:$I$150,B23,Planilha5!$R$1:RP$150) -> 0 | N23: =SUMIF(Planilha6!$I$1:$I$150,B23,Planilha6!$R$1:RQ$150) -> 0 | O23: =SUMIF(Planilha7!$I$1:$I$150,B23,Planilha7!$R$1:RR$150) -> 0 | P23: =SUMIF(Planilha8!$I$1:$I$150,B23,Planilha8!$R$1:RS$150) -> 0 | Q23: =SUMIF(Planilha9!$I$1:$I$150,B23,Planilha9!$R$1:RT$150) -> 0 | R23: =SUMIF(Planilha10!$I$1:$I$150,B23,Planilha10!$R$1:RU$150) -> 0 | S23: =SUMIF(Planilha11!$I$1:$I$150,B23,Planilha11!$R$1:RV$150) -> 0 | T23: =SUMIF(Planilha12!$I$1:$I$150,B23,Planilha12!$R$1:RW$150) -> 0 | V23: =SUMIF(Planilha13!$I$1:$I$150,B23,Planilha13!$R$1:RY$150) -> 0 | W23: =SUMIF(Planilha14!$I$1:$I$150,B23,Planilha14!$R$1:RZ$150) -> 0 | Y23: =SUMIF('2026'!$I$1:$I$150,B23,'2026'!$R$1:RQ$150) -> 0 | Z23: =SUM(V23:W23)-Y23 -> 0
A24: RECEITA LÍQUIDA DE VENDAS | I24: =SUMIF(Planilha1!$H$1:$H$110,A24,Planilha1!$R$1:$R$150) -> 508885.51 | J24: =SUMIF(Planilha2!$H$1:$H$110,A24,Planilha2!$R$1:$R$150) -> 422588.49 | K24: =SUMIF(Planilha3!$H$1:$H$110,A24,Planilha3!$R$1:$R$150) -> 496224.05 | L24: =SUMIF(Planilha4!$H$1:$H$110,A24,Planilha4!$R$1:$R$150) -> 409516.62 | M24: =SUMIF(Planilha5!$H$1:$H$110,A24,Planilha5!$R$1:$R$150) -> 517018.54 | N24: =SUMIF(Planilha6!$H$1:$H$110,A24,Planilha6!$R$1:$R$150) -> 378343.08 | O24: =SUMIF(Planilha7!$H$1:$H$110,A24,Planilha7!$R$1:$R$150) -> 365147.6 | P24: =SUMIF(Planilha8!$H$1:$H$110,A24,Planilha8!$R$1:$R$150) -> 490864.38 | Q24: =SUMIF(Planilha9!$H$1:$H$110,A24,Planilha9!$R$1:$R$150) -> 437414.82 | R24: =SUMIF(Planilha10!$H$1:$H$110,A24,Planilha10!$R$1:$R$150) -> 646119.11 | S24: =SUMIF(Planilha11!$H$1:$H$110,A24,Planilha11!$R$1:$R$150) -> 816123.12 | T24: =SUMIF(Planilha12!$H$1:$H$110,A24,Planilha12!$R$1:$R$150) -> 1104018 | V24: =SUMIF(Planilha13!$H$1:$H$110,A24,Planilha13!$R$1:$R$150) -> 875344.06 | W24: =SUMIF(Planilha14!$H$1:$H$110,A24,Planilha14!$R$1:$R$150) -> 647073.17 | Y24: =SUMIF('2026'!$H$1:$H$110,A24,'2026'!$R$1:$R$150) -> 1522417.2 | Z24: =SUM(V24:W24)-Y24 -> 0
Z25: =SUM(V25:W25)-Y25 -> 0
